Workbook
Name rel_date: Top!$B$3

Sheet Top
A1: Test Case Reference List for the Bluetooth Qualification Program (specifications external to Core).
A2: This TCRL includes qualification requirements for Hands-Free Profile (HFP). Published as part of TCRL.pkg101.p1.**
A3: Release Date: | B3: 46007 | C3: Specification | E3: Previous Requirements | G3: Updated Requirements
A4: Key to the Tables of the Test Case Reference List
A5: Table | B5: Contents | C5: Version | D5: Adoption Date | E5: TS | F5: ICS | G5: TS | H5: ICS | I5: Notes
A6: HFP 1.7.2 | B6: Hands-Free Profile 1.7.2 | C6: 1.7.2 | D6: 43480 | E6: HFP.TS.p30 | F6: HFP.ICS.p24 | G6: HFP.TS.p31 | H6: HFP.ICS.p25
A7: HFP 1.8 | B7: Hands-Free Profile 1.8 | C7: 1.8 | D7: 43935 | E7: HFP.TS.p30 | F7: HFP.ICS.p24 | G7: HFP.TS.p31 | H7: HFP.ICS.p25
A8: HFP 1.9 | B8: Hands-Free Profile 1.9 | C8: 1.9 | D8: 45181 | E8: HFP.TS.p30 | F8: HFP.ICS.p24 | G8: HFP.TS.p31 | H8: HFP.ICS.p25
A9: HFP 1.10 | B9: Hands-Free Profile 1.10 | C9: 1.10 | D9: 46006 | G9: HFP.TS.p31 | H9: HFP.ICS.p25
A11: Red text is used throughout this TCRL to designate all updates made since the previous TCRL release.
A13: * The Test System Alternatives columns of each TCRL include references to validated and commercially available test equipment that was in a validated state in time for the compilation of the rollup TCRL. If validation occurs later, in the interim between two published TCRLs, the newly validated test equipment can be used to satisfy existing Category A requirements in the same way as test equipment referenced by the TCRL, provided that a corresponding TCW, in the “Approved for Qualification” state, exists.
A14: ** TCRL Package Version Last Updated column only captures changes from TCRL 2017-1 and onward
A16: Notes:
B18: 1) Changes made due to an editorial TSE (severity rating 1) or a minor technical change (severity rating 2). See Release Notes tab for details.
B19: 2) The TSE impact affects the rollup TCRL only.
B20: 3) Changes made to IXIT.
A22: Tab Color Legend
B23: Sheet updated in this rollup TCRL.
B24: No changes to this sheet in this TCRL compared to the previous TCRL.
B25: Updates made to the Test System Alternatives column and/or the TC Category column in an individual TCRL, but there are no changes to test requirements compared to the previous TCRL Package.
A27: Bluetooth Qualification Testing: Members shall accomplish qualification testing using one of the following methods as defined by the test case category assigned to each test case:
A28: Test Case Category | B28: Test Status | C28: Equipment Requirements | F28: Evidence Requirements
A29: Category A | B29: Mandatory | C29: Validated and commercially available test equipment approved by the Bluetooth SIG as specified in the “Test Platform” column(s) of TCRL. | F29: Cat A tests in the areas RF, RFPHY, BB, LL, LMP, and HCI shall be performed and documented in a test report issued by a BQTF or BRTF. Cat A tests in all other areas can be performed by the Member, with evidence to be provided as detailed in Section 3.1.4 of the PRD (link in References section below).
A30: Category B | B30: Mandatory | C30: Optional to use either a Member-defined test setup that meets test requirements defined in Test Suites, or a validated test system if one is specified in the “Test Platform” column. | F30: Test setup, execution and results as detailed in Section 3.1.4 of the PRD (link in References section below).
A31: Category C | B31: Mandatory | C31: Member-defined test setup that meets test requirements defined in Test Suites. | F31: Declaration of tests performed and test results, no other evidence required.
A32: Category D | B32: Optional | C32: Member-defined test setup that meets test requirements defined in Test Suites. | F32: No evidence requirements.
A33: Category X | B33: Optional supplementary interoperability tests. These tests are aimed at scenarios that do not have a direct specification reference. The tests are recommended by the Bluetooth SIG to be run for improved interoperability, but they are not required to be executed as part of the Bluetooth Qualification program. | C33: Member-defined test setup that meets test requirements defined in Test Suites. | F33: No evidence requirements.
A35: References: For additional information regarding test categories, requirements, evidence, issue resolution, branding, and naming, please refer to the following:
A36: Program Reference Document (PRD) | C36: Launch Studio
A37: Specifications and Test Documents List | C37: Launch Studio - Getting Started
A38: Test Declaration Upload Best Practices | C38: TCRL Maintenance Process Document
A39: Bluetooth Brand Guide | C39: Bluetooth Help and Support
A40: TCRLs and Supplementary Documents | C40: Errata Process Document (EPD)
A42: Testing Errors: To report and resolve errors encountered in testing, follow the instructions below.
A43: Test Category | B43: Steps | G43: Action
A44: A | B44: 1. If the Test System used is PTS, file a PTS Issue either by visiting support.bluetooth.com or by selecting “PTS Issues” from the Help menu in PTS. Otherwise, go directly to Step 2. | G44: File PTS Issue
B45: 2. A Test Coverage Waiver (TCW) is required. File a TSE and follow the instructions to include a TCW request. | G45: File TSE/TCW
B46: 3. Once the TCW is granted, proceed with a member-defined test setup that meets test requirements defined in the Test Suites. Refer to Appendix A of the QPRD for evidence requirements. | G46: Review QPRD
A47: B or C | B47: 1. If the Test System used is PTS, file a PTS Issue either by visiting support.bluetooth.com or by selecting “PTS Issues” from the Help menu in PTS. Otherwise, go directly to Step 2. | G47: File PTS Issue
B48: 2. If an error is identified in the test requirements, file a TSE. If the error blocks a qualification, follow the instructions to include a TCW request. Otherwise, go to Step 3. | G48: File TSE/TCW
...

Sheet Deprecations
A1: Deprecated and Withdrawn Specification History
A2: Deprecation and Withdrawal announcements may occur at any time. This sheet is updated with the information from the Bluetooth Board of Directors' resolutions made at the time of the finalization of this TCRL Package and is provided for information only. Updates are made to this sheet only during a TCRL Package maintenance release cycle.
A3: References: For additional information regarding test categories, requirements, evidence, issue resolution, branding, and naming please refer to the TOP sheet of this rollup TCRL.
A4: For additional information regarding specification status and Deprecation and Withdrawal KBAs, the following Bluetooth SIG sites may be helpful:
A5: Specifications List
A6: Core Deprecation and Withdrawal Policy
A7: KBA - How Do Specification Deprecation or Withdrawal Impact Members Existing Qualified Products?
A8: KBA - Deprecation and Withdrawal (D&W)
A10: Release date: | B10: =rel_date -> 46007 | D10: Deprecated Specification | E10: Withdrawn Specification | F10: Requirements Last Maintained | H10: TCRL Package release requirements where the version moved to Deprecated
A11: Key to the Tables of the Test Case Reference List
A12: Table | B12: Contents | C12: Version | D12: Deprecation Date* | E12: Withdrawal Date** | F12: TS | G12: ICS | I12: Notes
A13: HFP 1.5 | B13: Hands-Free Profile 1.5​ | C13: 1.5 | D13: 44228 | E13: 44958 | F13: HFP.TS.p22 | G13: HFP.ICS.p18 | H13: Traditional TCRL 2020-1
A14: HFP 1.5.1 | B14: Hands-Free Profile 1.5​.1 | C14: 1.5.1 | D14: 44593 | E14: 44958 | F14: HFP.TS.p23 | G14: HFP.ICS.p18 | H14: Traditional TCRL 2021-2
A15: HFP 1.6 | B15: Hands-Free Profile 1.6 | C15: 1.6 | D15: 44228 | E15: 44958 | F15: HFP.TS.p22 | G15: HFP.ICS.p18 | H15: Traditional TCRL 2020-1
A16: HFP 1.6.1 | B16: Hands-Free Profile 1.6.1 | C16: 1.6.1 | D16: 44593 | E16: 45323 | F16: HFP.TS.p23 | G16: HFP.ICS.p18 | H16: Traditional TCRL 2021-2
A17: HFP 1.7 | B17: Hands-Free Profile 1.7 | C17: 1.7 | D17: 44228 | E17: 45323 | F17: HFP.TS.p22 | G17: HFP.ICS.p18 | H17: Traditional TCRL 2020-1
A18: HFP 1.7.1 | B18: Hands-Free Profile 1.7​.1 | C18: 1.7.1 | D18: 44228 | E18: 45323 | F18: HFP.TS.p22 | G18: HFP.ICS.p18 | H18: Traditional TCRL 2020-1
A20: Red text is used throughout this sheet to designate all updates made since the previous TCRL package release.
A22: Notes:
B23: 1) Deprecation dates in the future are still subject to Bluetooth Board of Directors decisions and are provided for information only.
B24: 2) Withdrawal dates in the future are still subject to Bluetooth Board of Directors decisions and are provided for information only.
B25: 3) Dates are scheduled from the Core Deprecation and Withdrawal Policy and subject to confirmation by the Bluetooth Board of Directors.
B26: 4) For Core Test Requirements, refer to the Core rollup TCRL release indicated in the TCRL Package release column for document details.

Sheet Disclaimer
A1: Disclaimer and Copyright Notice
A2: This document, regardless of its title or content, is not a Bluetooth Specification as defined in the Bluetooth Patent/Copyright License Agreement (“PCLA”) and Bluetooth Trademark License Agreement. Use of this document by members of Bluetooth SIG is governed by the membership and other related agreements between Bluetooth SIG Inc. (“Bluetooth SIG”) and its members, including the PCLA and other agreements posted on Bluetooth SIG’s website located at www.bluetooth.com. THIS DOCUMENT IS PROVIDED “AS IS” AND BLUETOOTH SIG, ITS MEMBERS, AND THEIR AFFILIATES MAKE NO REPRESENTATIONS OR WARRANTIES AND DISCLAIM ALL WARRANTIES, EXPRESS OR IMPLIED, INCLUDING ANY WARRANTY OF MERCHANTABILITY, TITLE, NON-INFRINGEMENT, FITNESS FOR ANY PARTICULAR PURPOSE, THAT THE CONTENT OF THIS DOCUMENT IS FREE OF ERRORS. TO THE EXTENT NOT PROHIBITED BY LAW, BLUETOOTH SIG, ITS MEMBERS, AND THEIR AFFILIATES DISCLAIM ALL LIABILITY ARISING OUT OF OR RELATING TO USE OF THIS DOCUMENT AND ANY INFORMATION CONTAINED IN THIS DOCUMENT, INCLUDING LOST REVENUE, PROFITS, DATA OR PROGRAMS, OR BUSINESS INTERRUPTION, OR FOR SPECIAL, INDIRECT, CONSEQUENTIAL, INCIDENTAL OR PUNITIVE DAMAGES, HOWEVER CAUSED AND REGARDLESS OF THE THEORY OF LIABILITY, AND EVEN IF BLUETOOTH SIG, ITS MEMBERS, OR THEIR AFFILIATES HAVE BEEN ADVISED OF THE POSSIBILITY OF SUCH DAMAGES. This document is proprietary to Bluetooth SIG. This document may contain or cover subject matter that is intellectual property of Bluetooth SIG and its members. The furnishing of this document does not grant any license to any intellectual property of Bluetooth SIG or its members. This document is subject to change without notice.
A3: Copyright © 2015–2025 by Bluetooth SIG, Inc. The Bluetooth word mark and logos are owned by Bluetooth SIG, Inc. Other third-party brands and names are the property of their respective owners.

Sheet HFP
A1: Test Case Reference List
A2: =Top!B6 & ", " & Top!C7 & ", " & Top!C8 & ", " & Top!C9 -> Hands-Free Profile 1.7.2, 1.8, 1.9, 1.10 | D2: Previous TS: | E2: =Top!E7 -> HFP.TS.p30 | H2: TS | I2: =Top!G7 -> HFP.TS.p31 | J2: Available Date: | K2: =rel_date -> 46007
A3: Release Date: | B3: =rel_date -> 46007 | D3: Previous ICS: | E3: =Top!F7 -> HFP.ICS.p24 | H3: ICS | I3: =Top!H7 -> HFP.ICS.p25 | J3: Available Date: | K3: =rel_date -> 46007
A4: Back to Top Sheet | D4: Previously published Test Requirements | H4: Updated Test Requirements through this Release
A5: TCID*** | B5: Description | C5: TCRL Package Version Last Updated | D5: TC Category | E5: Active Date | F5: Test System Alternatives | G5: Notes | H5: TC Category | I5: Active Date | J5: Test System Alternatives | K5: Notes*
A6: TCMT | B6: Test Case Mapping Table | C6: pkg101-addition | E6: 46055 | G6: TSE 27691 | I6: =$B$3+90 -> 46097 | K6: HFP v1.10 CF, HFP v1.10 CDI
A7: ICS | B7: Implementation Conformance Statement | C7: pkg101-addition | E7: 46055 | G7: TSE 27855 | I7: =$B$3+90 -> 46097 | K7: HFP v1.10 CF, HFP v1.10 CDI
A8: HFP/AG/ACC/BI-12-I to -13-I | B8: No longer used | C8: 2022-2
A9: HFP/AG/ACC/BI-14-C | B9: Codec Connection Setup Failure: mSBC | C9: 2022-2 | D9: A | E9: 46055 | F9: 3) | H9: A | I9: =$B$3+90 -> 46097 | J9: 3)
A10: HFP/AG/ACC/BV-08-I | B10: No longer used | C10: 2022-2
A11: HFP/AG/ACC/BV-09-C | B11: Codec Connection Setup with legacy peer with HF initiated | C11: 2022-2 | D11: A | E11: 46055 | F11: 3) | H11: A | I11: =$B$3+90 -> 46097 | J11: 3)
A12: HFP/AG/ACC/BV-10-I to -11-I | B12: No longer used | C12: 2022-2
A13: HFP/AG/ACC/BV-15-C | B13: Codec Connection Setup failure with AG initiated | C13: 2022-2 | D13: A | E13: 46055 | F13: 3) | H13: A | I13: =$B$3+90 -> 46097 | J13: 3)
A14: HFP/AG/ACC/BV-16-C | B14: HF Initiated Codec Connection Setup: CVSD | C14: 2022-2 | D14: B | E14: 46055 | F14: Member Defined | H14: B | I14: =$B$3+90 -> 46097 | J14: Member Defined
A15: HFP/AG/ACC/BV-17-C | B15: HF Initiated Codec Connection Setup: mSBC | C15: 2022-2 | D15: B | E15: 46055 | F15: Member Defined | H15: B | I15: =$B$3+90 -> 46097 | J15: Member Defined
A16: HFP/AG/ACC/BV-18-C | B16: AG Initiated Codec Connection Setup: CVSD | C16: 2022-2 | D16: A | E16: 46055 | F16: 3) | H16: A | I16: =$B$3+90 -> 46097 | J16: 3)
A17: HFP/AG/ACC/BV-19-C | B17: AG Initiated Codec Connection Setup: mSBC | C17: 2022-2 | D17: A | E17: 46055 | F17: 3) | H17: A | I17: =$B$3+90 -> 46097 | J17: 3)
A18: HFP/AG/ACC/BV-20-C | B18: AG Initiated Codec Connection Setup Following Initial Successful Codec Connection Setup: CVSD | C18: 2022-2 | D18: B | E18: 46055 | F18: Member Defined | H18: B | I18: =$B$3+90 -> 46097 | J18: Member Defined
A19: HFP/AG/ACC/BV-21-C | B19: AG Initiated Codec Connection Setup Following Initial Successful Codec Connection Setup: mSBC | C19: 2022-2 | D19: B | E19: 46055 | F19: Member Defined | H19: B | I19: =$B$3+90 -> 46097 | J19: Member Defined
A20: HFP/AG/ACC/BV-22-C | B20: Codec Connection Setup using Safe Settings: CVSD S1 | C20: 2023-1-addition | D20: B | E20: 46055 | F20: Member Defined | H20: B | I20: =$B$3+90 -> 46097 | J20: Member Defined
A21: HFP/AG/ACC/BV-23-C | B21: Codec Connection Setup using Safe Settings: mSBC T1 | C21: 2023-1-addition | D21: B | E21: 46055 | F21: Member Defined | H21: B | I21: =$B$3+90 -> 46097 | J21: Member Defined
A22: HFP/AG/ACC/BV-24-C | B22: Codec Connection Setup using Safe Settings: CVSD S4 | C22: 2023-1-addition | D22: B | E22: 46055 | F22: Member Defined | H22: B | I22: =$B$3+90 -> 46097 | J22: Member Defined
A23: HFP/AG/ACC/BV-25-C | B23: Codec Connection Setup using Safe Settings: mSBC T2 | C23: 2023-1-addition | D23: B | E23: 46055 | F23: Member Defined | H23: B | I23: =$B$3+90 -> 46097 | J23: Member Defined
A24: HFP/AG/ACC/BV-26-C | B24: Codec Connection Setup following failure to establish eSCO transport with T2 settings: mSBC | C24: 2023-1-addition | D24: B | E24: 46055 | F24: Member Defined | H24: B | I24: =$B$3+90 -> 46097 | J24: Member Defined
... A33: HFP/AG/ACC/BV-35-C | B33: Codec Connection Setup following failure to establish eSCO transport with T1 settings: LC3-SWB | C33: 2023-1-addition | D33: B | E33: 46055 | F33: Member Defined | H33: B | I33: =$B$3+90 -> 46097 | J33: Member Defined
A34: HFP/AG/ACR/BV-01-C | B34: Accept Audio Connection release | D34: A | E34: 46055 | F34: 3) | H34: A | I34: =$B$3+90 -> 46097 | J34: 3)
A35: HFP/AG/ACR/BV-02-C | B35: Initiate Audio Connection release | D35: A | E35: 46055 | F35: 3) | H35: A | I35: =$B$3+90 -> 46097 | J35: 3)
A36: HFP/AG/ACS/BI-14-C | B36: HF initiated eSCO audio setup with invalid bandwidth | D36: A | E36: 46055 | F36: 3) | H36: A | I36: =$B$3+90 -> 46097 | J36: 3)
A37: HFP/AG/ACS/BV-02-C | B37: AG initiated audio setup, HF is SCO only | D37: B | E37: 46055 | F37: 15) | H37: B | I37: =$B$3+90 -> 46097 | J37: 15)
A38: HFP/AG/ACS/BV-04-C | B38: HF initiated audio setup, HF is SCO only | D38: B | E38: 46055 | F38: 15) | H38: B | I38: =$B$3+90 -> 46097 | J38: 15)
A39: HFP/AG/ACS/BV-06-C | B39: AG initiated audio setup, HF has eSCO | D39: A | E39: 46055 | F39: 3) | H39: A | I39: =$B$3+90 -> 46097 | J39: 3)
A40: HFP/AG/ACS/BV-08-C | B40: HF initiated audio setup, HF has eSCO | D40: B | E40: 46055 | F40: 15) | H40: B | I40: =$B$3+90 -> 46097 | J40: 15)
A41: HFP/AG/ACS/BV-10-C | B41: AG initiated audio setup, HF has eSCO allows only SCO | D41: B | E41: 46055 | F41: 15) | H41: B | I41: =$B$3+90 -> 46097 | J41: 15)
A42: HFP/AG/ACS/BV-11-C | B42: HF initiated eSCO audio setup with 18 ms latency | D42: B | E42: 46055 | F42: 15) | H42: B | I42: =$B$3+90 -> 46097 | J42: 15)
A43: HFP/AG/ACS/BV-16-C | B43: HF requests eSCO audio setup with S4 settings | D43: B | E43: 46055 | F43: 15) | H43: B | I43: =$B$3+90 -> 46097 | J43: 15)
A44: HFP/AG/ACS/BV-18-C | B44: AG initiates eSCO audio setup over Secure Connections | D44: B | E44: 46055 | F44: Member Defined | H44: B | I44: =$B$3+90 -> 46097 | J44: Member Defined
A45: HFP/AG/ATA/BV-01-C | B45: Initiate audio transfer to the AG | D45: B | E45: 46055 | F45: 15) | H45: B | I45: =$B$3+90 -> 46097 | J45: 15)
... A49: HFP/AG/ATH/BV-03-C | B49: Accept audio transfer to HF | D49: A | E49: 46055 | F49: 3) | H49: A | I49: =$B$3+90 -> 46097 | J49: 3)
A50: HFP/AG/ATH/BV-04-C | B50: Accept HF initiated audio transfer to the HF with SLC | C50: 2018-1 | D50: A | E50: 46055 | F50: 3) | H50: A | I50: =$B$3+90 -> 46097 | J50: 3)
A51: HFP/AG/ATH/BV-05-C | B51: Initiate audio transfer to the HF with no SLC | D51: A | E51: 46055 | F51: 3) | H51: A | I51: =$B$3+90 -> 46097 | J51: 3)
...
