Workbook
Name rel_date: Top!$B$3

Sheet Top
A1: Test Case Reference List for the Bluetooth Qualification Program (specifications external to Core)
A2: This TCRL includes qualification requirements for specifications external to the Core. Published as part of TCRL.pkg101.p1.**
A3: Release Date: | B3: 46007 | C3: Specification | E3: Previous Requirements | G3: Updated Requirements
A4: Key to the Tables of the Test Case Reference List
A5: Table | B5: Contents | C5: Version | D5: Adoption Date | E5: TS | F5: ICS*** | G5: TS | H5: ICS | I5: Notes
A6: IOPT | B6: Interoperable Product Testing | C6: Ext to Core | D6: 0) | E6: IOPT.TS.p16 | F6: IOPT.ICS.p4 | G6: IOPT.TS.p17 | H6: IOPT.ICS.p5
A8: Red text is used throughout this rollup TCRL to designate all updates made since the previous TCRL Package release.
A10: * The Test System Alternatives columns of each TCRL include references to validated and commercially available test equipment that was in a validated state in time for the compilation of the rollup TCRL. If validation occurs later, in the interim between two published TCRL Packages, the newly validated Test System can be used to satisfy existing Category A requirements in the same way as a Test System referenced by the TCRL, provided that a corresponding TCW, in the “Approved for Qualification” state, exists.
A11: **The TCRL document and Package naming structure was modified to align with industry standards and enable flexibility in release timing. After the publication of TCRL 2025-2, TCRL Package numbering adopted the use of a generic, incrementing integer starting at pkg100, with the package number incremented by one with each publication. Individual rollup TCRLs within the TCRL Package are numbered with publication numbers (e.g., Mesh.TCRL.p14) and incremented by one each time that particular rollup TCRL is published. For more details, refer to the Document Naming and Marking Document (DNMD).
A12: *** The IOPT ICS was first published with TCRL 2024-1.
A15: Notes:
B16: 0) The IOPT TS uses table-driven test cases that are defined in other TS documents for GATT-based services, traditional profiles, and Mesh protocol that build on a generic test case structure defined in the GATT TS, the MESH TS, and the SDP TS. As such, there is no single adoption date and no single specification version.
B17: 1) Changes made due to an editorial TSE (severity rating 1) or a minor technical change (severity rating 2). See Release Notes tab for details.
A19: Tab Color Legend
B20: Sheet updated in this TCRL.
B21: No changes to this sheet in this TCRL compared to the previous TCRL.
B22: Updates made to the Test System Alternatives column and/or the TC Category column in an individual TCRL, but there are no changes to test requirements compared to the previous TCRL Package.
A25: References: For additional information regarding test categories, requirements, evidence, issue resolution, branding, and naming, please refer to the following:
A26: Qualification Program Reference Document (QPRD) | C26: Qualification Workspace
A27: Specifications and Test Documents List | C27: TCRL Maintenance Process Document
A28: Test Declaration Upload Best Practices | C28: Bluetooth Help and Support
A29: Bluetooth Brand Guide | C29: Errata Process Document (EPD)
A30: TCRLs and Supplementary Documents
A32: Testing Errors: To report and resolve errors encountered in testing, follow the instructions below.
A33: Test Category | B33: Steps | G33: Action
A34: A | B34: 1. If the Test System used is PTS, file a PTS Issue either by visiting support.bluetooth.com or by selecting “PTS Issues” from the Help menu in PTS. Otherwise, go directly to Step 2. | G34: File PTS Issue
B35: 2. A Test Coverage Waiver (TCW) is required. File a TSE and follow the instructions to include a TCW request. | G35: File TSE/TCW
B36: 3. Once the TCW is granted, proceed with a Member-defined test setup that meets test requirements defined in the Test Suites. Refer to Appendix A of the QPRD for evidence requirements. | G36: Review QPRD
A37: B or C | B37: 1. If the Test System used is PTS, file a PTS Issue either by visiting support.bluetooth.com or by selecting “PTS Issues” from the Help menu in PTS. Otherwise, go directly to Step 2. | G37: File PTS Issue
B38: 2. If an error is identified in the test requirements, file a TSE. If the error blocks a qualification, follow the instructions to include a TCW request. Otherwise, go to Step 3. | G38: File TSE/TCW
B39: 3. Proceed with a Member-defined test setup that meets test requirements defined in the Test Suites. Refer to Appendix A of the QPRD for evidence requirements. | G39: Review QPRD
A40: D or X | B40: 1. If the Test System used is PTS, file a PTS Issue either by visiting support.bluetooth.com or by selecting “PTS Issues” from the Help menu in PTS. Otherwise, go directly to Step 2. | G40: File PTS Issue
B41: 2. If an error is identified in the test requirements, file a TSE. For these test categories, no TCW is required. | G41: File TSE/TCW

Sheet Disclaimer
A1: Disclaimer and Copyright Notice
A2: This document, regardless of its title or content, is not a Bluetooth Specification as defined in the Bluetooth Patent/Copyright License Agreement (“PCLA”) and Bluetooth Trademark License Agreement. Use of this document by members of Bluetooth SIG is governed by the membership and other related agreements between Bluetooth SIG Inc. (“Bluetooth SIG”) and its members, including the PCLA and other agreements posted on Bluetooth SIG’s website located at www.bluetooth.com. THIS DOCUMENT IS PROVIDED “AS IS” AND BLUETOOTH SIG, ITS MEMBERS, AND THEIR AFFILIATES MAKE NO REPRESENTATIONS OR WARRANTIES AND DISCLAIM ALL WARRANTIES, EXPRESS OR IMPLIED, INCLUDING ANY WARRANTY OF MERCHANTABILITY, TITLE, NON-INFRINGEMENT, FITNESS FOR ANY PARTICULAR PURPOSE, THAT THE CONTENT OF THIS DOCUMENT IS FREE OF ERRORS. TO THE EXTENT NOT PROHIBITED BY LAW, BLUETOOTH SIG, ITS MEMBERS, AND THEIR AFFILIATES DISCLAIM ALL LIABILITY ARISING OUT OF OR RELATING TO USE OF THIS DOCUMENT AND ANY INFORMATION CONTAINED IN THIS DOCUMENT, INCLUDING LOST REVENUE, PROFITS, DATA OR PROGRAMS, OR BUSINESS INTERRUPTION, OR FOR SPECIAL, INDIRECT, CONSEQUENTIAL, INCIDENTAL OR PUNITIVE DAMAGES, HOWEVER CAUSED AND REGARDLESS OF THE THEORY OF LIABILITY, AND EVEN IF BLUETOOTH SIG, ITS MEMBERS, OR THEIR AFFILIATES HAVE BEEN ADVISED OF THE POSSIBILITY OF SUCH DAMAGES. This document is proprietary to Bluetooth SIG. This document may contain or cover subject matter that is intellectual property of Bluetooth SIG and its members. The furnishing of this document does not grant any license to any intellectual property of Bluetooth SIG or its members. This document is subject to change without notice.
A3: Copyright © 2024–2025 by Bluetooth SIG, Inc. The Bluetooth word mark and logos are owned by Bluetooth SIG, Inc. Other third-party brands and names are the property of their respective owners.

Sheet IOPT
A1: Test Case Reference List
A2: =Top!B6 -> Interoperable Product Testing | D2: Previous TS | E2: =Top!E$6 -> IOPT.TS.p16 | H2: TS | I2: =Top!G6 -> IOPT.TS.p17 | J2: Available Date: | K2: =rel_date -> 46007
A3: =Top!A3 -> Release Date: | B3: =rel_date -> 46007 | D3: Previous ICS | E3: =Top!F$6 -> IOPT.ICS.p4 | H3: ICS | I3: =Top!H6 -> IOPT.ICS.p5 | J3: Available Date: | K3: =rel_date -> 46007
A4: Back to Top Sheet | D4: Previously published Test Requirements | H4: Updated Test Requirements through this Release
A5: TCID**** | B5: Description | C5: TCRL Package Version Last Updated | D5: TC Category | E5: Active Date | F5: Test System Alternatives | G5: Notes | H5: TC Category | I5: Active Date | J5: Test System Alternatives | K5: Notes*
A6: TCMT | B6: Test Case Mapping Table | C6: pkg101-addition | E6: 46055 | G6: TSE 27936, CWS v1.0 | I6: =$B$3+90 -> 46097 | K6: VAS v1.0
A7: ICS | B7: Implementation Conformance Statement | C7: pkg101-addition | E7: 46055 | G7: CWS v1.0 | I7: =$B$3+90 -> 46097 | K7: VAS v1.0
A8: IOPT/3DSP/3DD/SDPR/BV-01-I | B8: SDP Record – 3DSP 3DD | C8: 2024-1 | D8: B | E8: 46055 | F8: Member Defined | H8: B | I8: =$B$3+90 -> 46097 | J8: Member Defined
A9: IOPT/3DSP/3DG/SDPR/BV-02-I | B9: SDP Record – 3DSP 3DG | C9: 2024-1 | D9: B | E9: 46055 | F9: Member Defined | H9: B | I9: =$B$3+90 -> 46097 | J9: Member Defined
A10: IOPT/A2DP/SNK/SDPR/BV-01-I | B10: SDP Record – Sink role | C10: 2024-1 | D10: B | E10: 46055 | F10: Member Defined | H10: B | I10: =$B$3+90 -> 46097 | J10: Member Defined
A11: IOPT/A2DP/SNK/CGSIT/SFC/BV-02-I | B11: SDP Future Compatibility – IUT is A2DP Sink | C11: 2024-1 | D11: B | E11: 46055 | F11: Member Defined | H11: B | I11: =$B$3+90 -> 46097 | J11: Member Defined
A12: IOPT/A2DP/SRC/SDPR/BV-01-I | B12: SDP Record – Source role | C12: 2024-1 | D12: B | E12: 46055 | F12: Member Defined | H12: B | I12: =$B$3+90 -> 46097 | J12: Member Defined
A13: IOPT/A2DP/SRC/CGSIT/SFC/BV-01-I | B13: SDP Future Compatibility – IUT is A2DP Source | C13: 2024-1 | D13: B | E13: 46055 | F13: Member Defined | H13: B | I13: =$B$3+90 -> 46097 | J13: Member Defined
A14: IOPT/ACS/SR/GATTDB/BV-01-I | B14: GATT service verification – ACS | C14: 2024-1 | D14: B | E14: 46055 | F14: Member Defined | H14: B | I14: =$B$3+90 -> 46097 | J14: Member Defined
A15: IOPT/ACS/SR/SGGIT/SDP/BV-01-I | B15: GATT-based service SDP record verification – ACS | C15: 2024-1 | D15: B | E15: 46055 | F15: Member Defined | H15: B | I15: =$B$3+90 -> 46097 | J15: Member Defined
A16: IOPT/AICS/SR/GATTDB/BV-01-I | B16: GATT service verification – AICS | C16: 2024-1 | D16: B | E16: 46055 | F16: Member Defined | H16: B | I16: =$B$3+90 -> 46097 | J16: Member Defined
A17: IOPT/AICS/SR/SGGIT/SDP/BV-01-I | B17: GATT-based service SDP record verification – AICS | C17: 2024-1 | D17: B | E17: 46055 | F17: Member Defined | H17: B | I17: =$B$3+90 -> 46097 | J17: Member Defined
A18: IOPT/AIOS/SR/GATTDB/BV-01-I | B18: GATT service verification – AIOS | C18: 2024-1 | D18: B | E18: 46055 | F18: Member Defined | H18: B | I18: =$B$3+90 -> 46097 | J18: Member Defined
A19: IOPT/AIOS/SR/SGGIT/SDP/BV-01-I | B19: GATT-based service SDP record verification – AIOS | C19: 2024-1 | D19: B | E19: 46055 | F19: Member Defined | H19: B | I19: =$B$3+90 -> 46097 | J19: Member Defined
... A52: IOPT/CGMS/SEN/SGGIT/SDP/BV-01-I | B52: GATT-based service SDP record verification – CGMS | C52: 2024-1 | D52: B | E52: 46055 | F52: Member Defined | H52: B | I52: =$B$3+90 -> 46097 | J52: Member Defined
A53: IOPT/CL/A2DP-SNK/SFC/BV-02-I | B53: No longer used | C53: 2024-1
A54: IOPT/CL/A2DP-SRC/SFC/BV-01-I | B54: No longer used | C54: 2024-1
A55: IOPT/CL/AVRCP-CT/SFC/BV-03-I | B55: No longer used | C55: 2024-1
A56: IOPT/CL/AVRCP-TG/SFC/BV-04-I | B56: No longer used | C56: 2024-1
A57: IOPT/CL/BIP-INT/SFC/BV-05-I | B57: No longer used | C57: 2024-1
A58: IOPT/CL/BPP-SD/SFC/BV-06-I | B58: No longer used | C58: 2024-1
A59: IOPT/CL/CTN-CCE/SFC/BV-07-I | B59: No longer used | C59: 2024-1
A60: IOPT/CL/DUN-DT/SFC/BV-08-I | B60: No longer used | C60: 2024-1
A61: IOPT/CL/FTP-CL/SFC/BV-09-I | B61: No longer used | C61: 2024-1
A62: IOPT/CL/HCRP-CL/SFC/BV-10-I | B62: No longer used | C62: 2024-1
A63: IOPT/CL/HDP-SNK/SFC/BV-11-I | B63: No longer used | C63: 2024-1
A64: IOPT/CL/HDP-SRC/SFC/BV-12-I | B64: No longer used | C64: 2024-1
... A81: IOPT/CL/VDP-SRC/SFC/BV-26-I | B81: No longer used | C81: 2024-1
A82: IOPT/CPS/SEN/GATTDB/BV-01-I | B82: GATT service verification – CPS | C82: 2024-1 | D82: B | E82: 46055 | F82: Member Defined | H82: B | I82: =$B$3+90 -> 46097 | J82: Member Defined
A83: IOPT/CPS/SEN/SGGIT/SDP/BV-01-I | B83: GATT-based service SDP record verification – CPS | C83: 2024-1 | D83: B | E83: 46055 | F83: Member Defined | H83: B | I83: =$B$3+90 -> 46097 | J83: Member Defined
A84: IOPT/CSCS/SEN/GATTDB/BV-01-I | B84: GATT service verification – CSCS | C84: 2024-1 | D84: B | E84: 46055 | F84: Member Defined | H84: B | I84: =$B$3+90 -> 46097 | J84: Member Defined
A85: IOPT/CSCS/SEN/SGGIT/SDP/BV-01-I | B85: GATT-based service SDP record verification – CSCS | C85: 2024-1 | D85: B | E85: 46055 | F85: Member Defined | H85: B | I85: =$B$3+90 -> 46097 | J85: Member Defined
A86: IOPT/CSIS/SR/GATTDB/BV-01-I | B86: GATT service verification – CSIS | C86: 2024-1 | D86: B | E86: 46055 | F86: Member Defined | H86: B | I86: =$B$3+90 -> 46097 | J86: Member Defined
A87: IOPT/CSIS/SR/SGGIT/SDP/BV-01-I | B87: GATT-based service SDP record verification – CSIS | C87: 2024-1 | D87: B | E87: 46055 | F87: Member Defined | H87: B | I87: =$B$3+90 -> 46097 | J87: Member Defined
A88: IOPT/CTES/SR/GATTDB/BV-01-I | B88: GATT service verification – CTES | C88: 2024-1 | D88: B | E88: 46055 | F88: Member Defined | H88: B | I88: =$B$3+90 -> 46097 | J88: Member Defined
...

Sheet TCID History
A1: TCID History
A2: TCID renaming may happen from time to time as conventions change. This is a list of the past TCID names used for currently active TCIDs as an informative reference; the most recent TCIDs are listed first. Fixes due to typos are not tracked. Once a test case is removed or has been converted to GGIT, its previous TCID History is removed.
A3: Changes to TCIDs that converted -I test cases to -C are not tracked on this sheet. For details on these changes, see the individual layer sheets in TCRLs 2023-1 and 2024-1.
A5: Layer | B5: Current TCID | C5: Previous TCID(s)
A6: HFP, IOPT | B6: HFP/AG/COD/BV-01-C | C6: IOPT/CL/HF-AG/COD/BV-02-I, TP/COD/BV-02-I
