Workbook
Name _Toc125985155: 'Release Notes'!$E$122
Name rel_date: [1]Top!$B$2
Name rel_date: Top!$B$2

Sheet Top
A1: Test Case Reference List for the Bluetooth Qualification Program (Bluetooth Core 4.2–6.2 Implementations).
A2: Release Date | B2: 45965 | C2: Specification | E2: Previous Requirements | G2: Updated Requirements
A3: Key to the Tables of the TCRL
A4: Table | C4: Contents | D4: Volume, Part, Version(s) | E4: TS | F4: ICS | G4: TS | H4: ICS | I4: Notes
A5: RF | B5: BR/EDR Core Controller | C5: BR/EDR Radio Physical Layer Conformance | D5: Vol 2 Part A, 4.2–6.2 | E5: RF.TS.p35 | F5: RF.ICS.p24 | G5: RF.TS.p36 | H5: RF.ICS.p24 | I5: 4) TSE 25827 5)
A6: BB | C6: Baseband Conformance | D6: Vol 2 Part B, 4.2–6.2 | E6: BB.TS.p38 | F6: BB.ICS.p27 | G6: BB.TS.p39 | H6: BB.ICS.p28 | I6: 5)
A7: LMP | C7: Link Manager Protocol Conformance | D7: Vol 2 Part C, 4.2–6.2 | E7: LMP.TS.p48 | F7: LMP.ICS.p40 | G7: LMP.TS.p49 | H7: LMP.ICS.p41 | I7: 5)
A8: SEC | C8: BR/EDR Security Conformance | D8: Vol 2 Part H, 4.2–6.2 | E8: LMP.TS.p48 | F8: SEC.ICS.p0 | G8: LMP.TS.p49 | H8: SEC.ICS.p0
A9: 80211PAL | B9: AMP Core Controller | C9: 802.11 PAL Conformance | D9: Vol 5 Part A, 4.2–5.2 | E9: 80211PAL.TS.p13 | F9: 80211PAL.ICS.p9 | G9: 80211PAL.TS.p13 | H9: 80211PAL.ICS.p9
A10: RFPHY | B10: LE Controller | C10: LE Radio Physical Layer Conformance | D10: Vol 6 Part A, 4.2–6.2 | E10: RFPHY.TS.p23 | F10: RFPHY.ICS.p12 | G10: RFPHY.TS.p24 | H10: RFPHY.ICS.p13 | I10: 3) TSEs 27815, 27822, 28075 4) TSE 25828, 27158 5)
A11: LL | C11: Link Layer Conformance | D11: Vol 6 Part B, 4.2–6.2 | E11: LL.TS.p26 | F11: LL.ICS.p24 | G11: LL.TS.p27 | H11: LL.ICS.p25 | I11: 3) TSE 27724 4) TSE 27692 5)
A12: LE SEC | C12: LE LL Security Conformance | D12: Vol 6 Part E, 4.2–6.2 | E12: LL.TS.p26 | F12: LESEC.ICS.p1 | G12: LL.TS.p27 | H12: LESEC.ICS.p1 | I12: 3) TSE 27724 4) TSE 27692 5)
A13: IAL | C13: Isochronous Adaptation Layer Conformance | D13: Vol 6 Part G, 5.2–6.2 | E13: IAL.TS.p9 | F13: IAL.ICS.p3 | G13: IAL.TS.p10 | H13: IAL.ICS.p3 | I13: 3) TSE 27725
A14: CS | C14: Channel Sounding Conformance | D14: Vol 6 Part H, 6.0–6.2 | E14: CS.TS.p2 | F14: CS.ICS.p2 | G14: CS.TS.p3 | H14: CS.ICS.p3 | I14: 4) TSE 27907 (CSAA)
A15: HCI | B15: Host Controller Interface | C15: Host Controller Interface Conformance (Lower HCI role) | D15: Vol 2 Part E, 4.2–6.2 | E15: HCI.TS.p37 | F15: HCI.ICS.p32 | G15: HCI.TS.p38 | H15: HCI.ICS.p33 | I15: 4) TSE 27140 5)
A16: UHCI | C16: Host Controller Interface Conformance (Upper HCI role) | D16: Vol 2 Part E, 4.2–6.2 | E16: HCI.TS.p37 | F16: UHCI.ICS.p2 | G16: HCI.TS.p38 | H16: UHCI.ICS.p3 | I16: 4) TSE 27140 5)
A17: L2CAP | B17: Core Host | C17: Logical Link Control and Adaptation Protocol Conformance | D17: Vol 3 Part A, 4.2–6.2 | E17: L2CAP.TS.p40 | F17: L2CAP.ICS.p28 | G17: L2CAP.TS.p41 | H17: L2CAP.ICS.p29 | I17: 4) TSE 27460 5)
A18: SDP | C18: Service Discovery Protocol Conformance | D18: Vol 3 Part B, 4.2–6.2 | E18: SDP.TS.p24 | F18: SDP.ICS.p24 | G18: SDP.TS.p25 | H18: SDP.ICS.p25 | I18: 3) TSE 28089 4) TSEs 27439, 27748 5)
A19: GAP | C19: Generic Access Profile Conformance | D19: Vol 3 Part C, 4.2–6.2 | E19: GAP.TS.p48 | F19: GAP.ICS.p44 | G19: GAP.TS.p49 | H19: GAP.ICS.p45 | I19: 4) TSE 27509 5)
A20: A2MP | C20: AMP Manager Conformance | D20: Vol 3 Part E, 4.2–5.2 | E20: A2MP.TS.p8 | F20: A2MP.ICS.p8 | G20: A2MP.TS.p8 | H20: A2MP.ICS.p8
A21: ATT | C21: Attribute Protocol Conformance | D21: Vol 3 Part F, 4.2–6.2 | E21: GATT.TS.p28 | F21: ATT.ICS.p14 | G21: GATT.TS.p29 | H21: ATT.ICS.p15 | I21: 4) TSE 25413 5)
A22: GATT | C22: Generic Attribute Profile Conformance | D22: Vol 3 Part G, 4.2–6.2 | E22: GATT.TS.p28 | F22: GATT.ICS.p21 | G22: GATT.TS.p29 | H22: GATT.ICS.p22 | I22: 4) TSE 25413 5)
A23: SM | C23: Security Manager Conformance | D23: Vol 3 Part H, 4.2–6.2 | E23: SM.TS.p28 | F23: SM.ICS.p12 | G23: SM.TS.p29 | H23: SM.ICS.p13 | I23: 4) TSE 27423 5)
A24: 80211MP | B24: External to Core | C24: IEEE 802.11 PHY and MAC Layers | D24: IEEE 802.11-2007 (1) | E24: 80211MP.TS.p7 | F24: 80211MP.ICS.p7 | G24: 80211MP.TS.p7 | H24: 80211MP.ICS.p7
A25: CORE ICS | B25: CORE ICS | C25: Core Configurations (CORE) | D25: Vol 0 Part D, 6.0–6.2* | E25: N/A | F25: CORE.ICS.p3 | G25: N/A | H25: CORE.ICS.p4 | I25: 2) TSE 27886 (LETM) 2) TSE 27934 (SCI) 2) TSE 27576
A27: Red text is used throughout this rollup TCRL to designate all updates made since the previous TCRL Package release.
A29: * Please note that this also applies to v4.2–v5.4 amended versions.
A30: Note: The Test System Alternatives columns of each TCRL include references to validated and commercially available test equipment that was in a validated state in time for the compilation of the rollup TCRL. If validation occurs later, in the interim between two published TCRL Packages, the newly validated Test System can be used to satisfy existing Category A requirements in the same way as a Test System referenced by the TCRL, provided that a corresponding TCW, in the “Approved for Qualification” state, exists.
A32: Adoption Dates
A33: Specification Version | B33: Adoption Date
A34: 6.2 | B34: 45964
A35: 6.1 | B35: 45782
A36: 6 | B36: 45531
A37: 5.4 | B37: 44957
A38: 5.3 | B38: 44383
A39: 5.2 | B39: 43830
A40: 5.1 | B40: 43480
A41: ESR11 | B41: 43088
A42: CSA6 | B42: 42928
A43: ESR10 | B43: 42710
...

Sheet Deprecations
A1: Deprecated and Withdrawn Specification History
A2: Deprecation and Withdrawal announcements may occur at any time. This sheet is updated with the information from the Bluetooth Board of Directors' resolutions made at the time of the finalization of this TCRL Package and is provided for information only. Updates are made to this sheet only during a TCRL Package maintenance release cycle.
A3: References: For additional information regarding test categories, requirements, evidence, issue resolution, branding, and naming please refer to the TOP sheet of this rollup TCRL
A4: For additional information regarding specification status and Deprecation and Withdrawal KBAs, the following Bluetooth SIG sites may be helpful:
A5: Specifications List
A6: Core Deprecation and Withdrawal Policy
A7: KBA - How Do Specification Deprecation or Withdrawal Impact Members Existing Qualified Products?
A8: KBA - Deprecation and Withdrawal (D&W)
A10: Last updated date: | B10: 45965 | D10: Deprecated Specification | E10: Withdrawn Specification | F10: Requirements Last Maintained | H10: TCRL Package release requirements where the version moved to Deprecated
A11: Key to the Tables of the Test Case Reference List
A12: Table | B12: Contents | C12: Version | D12: Deprecation Date* | E12: Withdrawal Date** | F12: TS | G12: ICS | I12: Notes
A13: 2.0+ EDR | B13: Core Specification 2.0 + EDR | C13: 2.0 | D13: 41956 | E13: 43493 | F13: 4) | G13: 4) | H13: Core TCRL 2015-1
A14: 2.1+ EDR | B14: Core Specification 2.1 + EDR | C14: 2.1 | D14: 43493 | E14: 44013 | F14: 4) | G14: 4) | H14: Core TCRL 2018-2
A15: 3.0+ HS | B15: Core Specification 3.0 + HS | C15: 3.0 | D15: 43493 | E15: 44013 | F15: 4) | G15: 4) | H15: Core TCRL 2018-2
A16: 4.0 | B16: Core Specification 4.0 | C16: 4.0 | D16: 43493 | E16: 44593 | F16: 4) | G16: 4) | H16: Core TCRL 2018-2
A17: 4.1 | B17: Core Specification 4.1 | C17: 4.1 | D17: 43493 | E17: 44958 | F17: 4) | G17: 4) | H17: Core TCRL 2018-2
A18: 4.2 | B18: Core Specification 4.2 | C18: 4.2 | D18: 46054 | E18: 47880 | F18: TBD | G18: TBD | H18: TBD
A19: 5 | B19: Core Specification 5.0 | C19: 5.0 | D19: 46419 | E19: 48245 | F19: TBD | G19: TBD | H19: TBD
A20: 5.1 | B20: Core Specification 5.1*** | C20: 5.1 | D20: 47150 | E20: 48976 | F20: TBD | G20: TBD | H20: TBD
A21: 5.2 | B21: Core Specification 5.2*** | C21: 5.2 | D21: 47515 | E21: 49341 | F21: TBD | G21: TBD | H21: TBD
A22: 5.3 | B22: Core Specification 5.3*** | C22: 5.3 | D22: 48030 | E22: 49857 | F22: TBD | G22: TBD | H22: TBD
A23: 5.4 | B23: Core Specification 5.4*** | C23: 5.4 | D23: 48611 | E23: 50437 | F23: TBD | G23: TBD | H23: TBD
A24: 6 | B24: Core Specification 6.0*** | C24: 6.0 | D24: 49341 | E24: 51167 | F24: TBD | G24: TBD | H24: TBD
A25: 3DSP 1.0 | B25: 3D Synchronization Profile 1.0 | C25: 1.0 | D25: 41751 | E25: 44593 | F25: 3DSP.TS.1.0.1 | G25: 3DSP.ICS.1.0.2 | H25: Traditional TCRL 2015-1
A26: 3DSP 1.0.1 | B26: 3D Synchronization Profile 1.0.1 | C26: 1.0.1 | D26: 44228 | E26: 44593 | F26: 3DSP.TS.1.0.3.1 | G26: 3DSP.ICS.1.0.3.1 | H26: Traditional TCRL 2020-1
A27: 3DSP 1.0.2 | B27: 3D Synchronization Profile 1.0.2 | C27: 1.0.2 | D27: 44228 | E27: 44593 | F27: 3DSP.TS.1.0.3.1 | G27: 3DSP.ICS.1.0.3.1 | H27: Traditional TCRL 2020-1
A28: A2DP 1.0 | B28: Advanced Audio Dist. Profile 1.0​ | C28: 1.0 | D28: 44593 | E28: 44958 | F28: A2DP.TS.p16 | G28: A2DP.ICS.p14 | H28: Traditional TCRL 2021-2
A29: A2DP 1.2 | B29: Advanced Audio Dist. Profile 1.2 | C29: 1.2 | D29: 46784 | E29: 47515 | F29: TBD | G29: TBD | H29: TBD
A30: A2DP 1.3 | B30: Advanced Audio Dist. Profile 1.3 | C30: 1.3 | D30: 44228 | E30: 45323 | F30: A2DP.TS.1.3.2.1 | G30: A2DP.ICS.1.3.2.2 | H30: Traditional TCRL 2020-1
A31: A2DP 1.3.1 | B31: Advanced Audio Dist. Profile 1.3.1 | C31: 1.3.1 | D31: 44228 | E31: 45323 | F31: A2DP.TS.1.3.2.1 | G31: A2DP.ICS.1.3.2.2 | H31: Traditional TCRL 2020-1
A32: AVCTP 1.0 | B32: Audio/Video Control Transport Protocol 1.0 | C32: 1.0 | D32: 44593 | E32: 44958 | F32: AVCTP.TS.1.4.1 | G32: AVCTP.ICS.1.4.2 | H32: Traditional TCRL 2021-2
A33: AVCTP 1.2 | B33: Audio/Video Control Transport Protocol 1.2 | C33: 1.2 | D33: 44593 | E33: 44958 | F33: AVCTP.TS.1.4.1 | G33: AVCTP.ICS.1.4.2 | H33: Traditional TCRL 2021-2
A34: AVCTP 1.3 | B34: Audio/Video Control Transport Protocol 1.3 | C34: 1.3 | D34: 41479 | E34: 44958 | F34: AVCTP.TS.1.4.0 | G34: AVCTP.ICS.1.4.0 | H34: Traditional TCRL 2015-1
A35: AVDTP 1.0 | B35: A/V Distribution Transport Protocol 1.0​ | C35: 1.0 | D35: 44593 | E35: 44958 | F35: AVDTP.TS.p19 | G35: AVDTP.ICS.1.3.4 | H35: Traditional TCRL 2021-2
A36: AVDTP 1.2 | B36: A/V Distribution Transport Protocol 1.2 | C36: 1.2 | D36: 44958 | E36: 45323 | F36: AVDTP.TS.p19 | G36: AVDTP.ICS.1.3.4 | H36: Traditional TCRL 2022-1
A37: AVRCP 1.0 | B37: Audio/Video Remote Control Profile 1.0 | C37: 1.0 | D37: 44593 | E37: 44958 | F37: AVRCP.TS.1.6.2.2 | G37: AVRCP.ICS.1.6.2.0 | H37: Traditional TCRL 2021-2
A38: AVRCP 1.3 | B38: Audio/Video Remote Control Profile 1.3 | C38: 1.3 | D38: 44958 | E38: 46419 | F38: AVRCP.TS.1.6.2.2 | G38: AVRCP.ICS.1.6.2.0 | H38: Traditional TCRL 2022-1
A39: AVRCP 1.4 | B39: Audio/Video Remote Control Profile 1.4 | C39: 1.4 | D39: 41479 | E39: 44958 | F39: AVRCP.TS.1.6.0 | G39: AVRCP.ICS.1.6.0 | H39: Traditional TCRL 2015-1
A40: AVRCP 1.6 | B40: Audio/Video Remote Control Profile 1.6 | C40: 1.6 | D40: 44228 | E40: 45323 | F40: AVRCP.TS.1.6.2.2 | G40: AVRCP.ICS.1.6.2.0 | H40: Traditional TCRL 2020-1
A41: AVRCP 1.6.1 | B41: Audio/Video Remote Control Profile 1.6.1 | C41: 1.6.1 | D41: 44228 | E41: 45323 | F41: AVRCP.TS.1.6.2.2 | G41: AVRCP.ICS.1.6.2.0 | H41: Traditional TCRL 2020-1
...

Sheet Expedited Errata TS&ICS impact
A1: Expedited Errata: TS & ICS impact
A2: This sheet informatively summarizes the qualification requirement changes and additions connected to the expedited specification erratum as defined when first qualifiable.
A3: Note that qualification requirement applicability to an IUT is always determined through the combination of supported features in the ICS, the selection logic in the TCMT, and the status of each test case listed in the rollup TCRL.
A5: Erratum Nr | B5: Adoption Date | C5: Description
A6: 11838 | B6: 43690 | C6: Encryption Key Size Updates
A7: 10734 | B7: 43297 | C7: Pairing Updates
A8: 18552 | B8: 45454 | C8: Access to additional CIS parameters
A9: 24617 | B9: 45531 | C9: Security changes - batch 1
A10: 25800 | B10: 45531 | C10: Expedited fixes to Frame Space Update
A11: 27096 | B11: 45782 | C11: Pause Encryption should be mandatory to support with encryption
A14: Erratum 11838 Encryption Key Size Updates: TS and ICS impact
A15: The erratum was first qualifiable in TCRL 2019-1, with its qualification requirements available from 20-Aug-2019 and active from 20-Feb-2020.
A16: HCI
A17: ICS changes | B17: TCID/Item number | C17: Description
A18: Modified Condition | B18: HCI 16/30 | C18: HCI Read Encryption Key Size Command
A19: GAP
A20: TS changes | B20: TCID/Item number | C20: Description
A21: New TC | B21: GAP/SEC/SEM/BI-01-C | C21: Security Mode 2, Responder - Invalid Encryption Key Size
A22: New TC | B22: GAP/SEC/SEM/BI-02-C | C22: Security Mode 4 Level 2, Responder - Invalid Encryption Key Size
A23: New TC | B23: GAP/SEC/SEM/BI-03-C | C23: Security Mode 4 Level 3, Responder - Invalid Encryption Key Size
A24: New TC | B24: GAP/SEC/SEM/BI-04-C | C24: Security Mode 4 Level 4, Responder - Invalid Encryption Key Size
A25: New TC | B25: GAP/SEC/SEM/BI-05-C | C25: Security Mode 2, Initiator - Invalid Key Size
A26: New TC | B26: GAP/SEC/SEM/BI-06-C | C26: Security Mode 4 Level 2, Initiator - Invalid Encryption Key Size
A27: New TC | B27: GAP/SEC/SEM/BI-07-C | C27: Security Mode 4 Level 3, Initiator - Invalid Encryption Key Size
A28: New TC | B28: GAP/SEC/SEM/BI-08-C | C28: Security Mode 4 Level 4, Initiator - Invalid Encryption Key Size
A29: New TC | B29: GAP/SEC/SEM/BI-09-C | C29: LE Security Mode 1 Level 4, Peripheral - Invalid Encryption Key Size
A30: New TC | B30: GAP/SEC/SEM/BI-10-C | C30: LE Security Mode 1 Level 4, Central - Invalid Encryption Key Size
A31: New TC | B31: GAP/SEC/SEM/BI-11-C | C31: Security Mode 4 Level 1, Responder - Invalid Encryption Key Size
... A34: New ICS item | B34: GAP 2/12 | C34: 56-bit minimum encryption key size
A35: LMP
A36: TS changes | B36: TCID/Item number | C36: Description
A37: New TC | B37: LMP/ENC/BV-51-C | C37: Key Size Negotiation as Peripheral - E0, Acceptor
A38: New TC | B38: LMP/ENC/BV-52-C | C38: Key Size Negotiation as Peripheral - AES, Acceptor
A39: New TC | B39: LMP/ENC/BV-53-C | C39: Key Size Negotiation as Central - E0
A40: New TC | B40: LMP/ENC/BV-54-C | C40: Key Size Negotiation as Central - AES
A41: New TC | B41: LMP/ENC/BV-55-C | C41: Key Size Negotiation as Peripheral - E0, Initiator
A42: New TC | B42: LMP/ENC/BV-56-C | C42: Key Size Negotiation as Peripheral - AES, Initiator
A43: SUM.ICS
A44: ICS changes | B44: TCID/Item number | C44: Description
A45: New ICS item | B45: SUM ICS 21/19 | C45: Core Controller/ Core Erratum 11838 Key Size Updates
...

Sheet Disclaimer
A1: Disclaimer and Copyright Notice
A2: This document, regardless of its title or content, is not a Bluetooth Specification as defined in the Bluetooth Patent/Copyright License Agreement (“PCLA”) and Bluetooth Trademark License Agreement. Use of this document by members of Bluetooth SIG is governed by the membership and other related agreements between Bluetooth SIG Inc. (“Bluetooth SIG”) and its members, including the PCLA and other agreements posted on Bluetooth SIG’s website located at www.bluetooth.com. THIS DOCUMENT IS PROVIDED “AS IS” AND BLUETOOTH SIG, ITS MEMBERS, AND THEIR AFFILIATES MAKE NO REPRESENTATIONS OR WARRANTIES AND DISCLAIM ALL WARRANTIES, EXPRESS OR IMPLIED, INCLUDING ANY WARRANTY OF MERCHANTABILITY, TITLE, NON-INFRINGEMENT, FITNESS FOR ANY PARTICULAR PURPOSE, THAT THE CONTENT OF THIS DOCUMENT IS FREE OF ERRORS. TO THE EXTENT NOT PROHIBITED BY LAW, BLUETOOTH SIG, ITS MEMBERS, AND THEIR AFFILIATES DISCLAIM ALL LIABILITY ARISING OUT OF OR RELATING TO USE OF THIS DOCUMENT AND ANY INFORMATION CONTAINED IN THIS DOCUMENT, INCLUDING LOST REVENUE, PROFITS, DATA OR PROGRAMS, OR BUSINESS INTERRUPTION, OR FOR SPECIAL, INDIRECT, CONSEQUENTIAL, INCIDENTAL OR PUNITIVE DAMAGES, HOWEVER CAUSED AND REGARDLESS OF THE THEORY OF LIABILITY, AND EVEN IF BLUETOOTH SIG, ITS MEMBERS, OR THEIR AFFILIATES HAVE BEEN ADVISED OF THE POSSIBILITY OF SUCH DAMAGES. This document is proprietary to Bluetooth SIG. This document may contain or cover subject matter that is intellectual property of Bluetooth SIG and its members. The furnishing of this document does not grant any license to any intellectual property of Bluetooth SIG or its members. This document is subject to change without notice.
A3: Copyright © 2015–2025 by Bluetooth SIG, Inc. The Bluetooth word mark and logos are owned by Bluetooth SIG, Inc. Other third-party brands and names are the property of their respective owners.
A684: 2) Category B starting on 2020-Jan-15, Category A starting 2020-Apr-15

Sheet Release Notes
A1: Release notes Core.TCRL.p49
A2: Published as part of TCRL.pkg101.p0
A3: *Note: The "Impact Rating" column below refers to TSE impact as defined in the Errata Process Document (EPD), available on the Bluetooth SIG member website. All TSEs for this rollup TCRL release are listed in the table below, but only TSEs with an impact rating of 3 or higher (i.e., TSEs that are not purely editorial) are listed in the individual layer tabs, with the exception of TSEs impacting the ICS and TCMT.
A4: **Note: The CRs associated with the Core v6.2 release are noted within this document according to the associated feature involved. LETM (LE Test Mode Enhancements), CSAA (Channel Sounding Amplitude-based Attack Resilience), and SCI (Shorter Connection Intervals).
A6: TSE | B6: Layer | C6: Document | D6: Impact Rating* | E6: Summary
A7: 27575 | B7: ATT | C7: ICS | D7: 1 | E7: Updated the ILDs for ATT 7/2 and ATT 7/3.
A8: 26825 | B8: BB | C8: ICS | D8: 1 | E8: Updated the status value for Item 10/7. Marked condition C.1 for Table 10 as no longer used.
A9: 27061 | B9: BB | C9: ICS | D9: 1 | E9: In Table 2, updated the status for Item 2/4; updated the reference for Items 2/7 and 2/8; added Items 4a and 7a; added an ILD column; updated conditions C.1, C.2, C.4, and C.5; and added C.6. In Table 5a, updated the status for Item 5a/3, updated all existing conditions, and added condition C.6. Added Section 3, Bridge mapping between BB ICS and LMP ICS (informational). Replaced all cross-references to reference [4] with cross-references to [1]. Updated the references list including the addition of a new reference [6].
A10: 27209 | B10: BB | C10: ICS | D10: 1 | E10: Updated language per the current ICS template in Items 1a/1 – 1a/3 and condition C.2 in Table 1a; C.1 and C.3 in Table 5a; and C.1 and C.3 in Table 6a.
A11: 26912 | B11: BB | C11: TS | D11: 2 | E11: Updated the test procedure for BB/PROT/ARQ/BV-33-C, -35-C, -37-C, -43-C, and -45-C.
A12: 27200 | B12: BB | C12: TCMT | D12: 2 | E12: Updated the TCMT entry to remove BB 2/7 for BB/PROT/ARQ/BV-40-C and -41-C and BB/PROT/CON/BV-10-C – -14-C.
A13: 27576 | B13: CORE | C13: ICS | D13: 1 | E13: Removed deleted GAP references from conditional C.1 in Table 20a.
A14: 27907 | B14: Core Test CR (CSAA) | C14: ICS, TS, TCMT, IXIT | D14: 4 | E14: CS.ICS: To support the CSAA feature added for Core v6.2, added 2/16 and associated conditional C.3. CS.TS: To support the CSAA feature in Core v6.2, added a new reference to Core v6.2, a new section entitled “Amplitude-based Attack NADM, Square Wave Test Strategy”, and new Amplitude-based Attack NADM, Square Wave tests CS/NAD/REF/BV-37-C – -48-C. Updated the TCMT accordingly. IXIT: Added IXIT values to the CS tab to support the updates for the CSAA feature in Core v6.2.
A15: 27886 | B15: Core Test CR (LETM) | C15: ICS, TS, TCMT | D15: 4 | E15: Core ICS: Incorporated LE_Test_Mode_Enhancements_TEST_CR_r10 to integrate the LE Test Mode Enhancements feature for Core v6.2. Added item 62 to Table 1a and accompanying conditional C.8. Added 2/62. Added 2a/62 and accompanying conditional C.8. Added 2b/62 and accompanying conditional C.8. LL.ICS: Incorporated LE_Test_Mode_Enhancements_TEST_CR_r10 to integrate the LE Test Mode Enhancements feature for Core v6.2. Added items 63–68 and accompanying conditionals C.58–C.60 to Table 9. Added a reference to Core v6.2 to the References section. Added PDUs to the PDU table. HCI.ICS: Incorporated LE_Test_Mode_Enhancements_TEST_CR_r10 to integrate the LE Test Mode Enhancements feature for Core v6.2. Added items 23–25 and accompanying conditionals C.80–C.81 to Table 17. Added a reference to Core v6.2 to the References section. LL.TS: Incorporated LE_Test_Mode_Enhancements_TEST_CR_r10 to integrate the LE Test Mode Enhancements feature for Core v6.2. Added a new reference to all files to cover the Core v6.2 adoption. In the PAC file, added a new section for UTP OTA Mode, including new TCs LL/PAC/BI-01-C and LL/PAC/BV-01-C – -04-C. Updated the TCMT accordingly. UHCI.ICS: Incorporated LE Test Mode Enhancements changes needed to support Core v6.2. Added a reference to Core v6.2 and added 0/62 with required conditional C.9.
A16: 27934 | B16: Core Test CR (SCI) | C16: ICS, TS, TCMT | D16: 4 | E16: Core ICS: Incorporated Shorter Connection Intervals Test CR r13 to integrate the Shorter Connection Intervals feature for Core v6.2. Added a reference to Core v6.2 to the References section; added item 1/62; added item 1a/62 and accompanying conditional C.8; added item 1b/62 and accompanying conditional C.8. LL.ICS: Incorporated Shorter Connection Intervals Test CR r13 to integrate the Shorter Connection Intervals feature for Core v6.2. Added a reference to Core v6.2 to the References section; added items 9/69 and 9/70 and accompanying conditional C.61. Added associated feature bits to the mapping table in Section 2. Added PDUs to the PDU table. HCI.ICS: Incorporated Shorter Connection Intervals Test CR r13 to integrate the Shorter Connection Intervals feature for Core v6.2. Added a reference to Core v6.2 to the References section; added items 7/53, 7/54, and 7/55 and accompanying conditional C.85; added items 12/4a and 12/5a and accompanying conditional C.86. LL.TS: Incorporated Shorter Connection Intervals Test CR r13 to integrate the Shorter Connection Intervals feature for Core v6.2. Added a reference to Core v6.2 to the References section; in the CON section, added new TCs LL/CON/CEN/BI-20-C – -23-C, LL/CON/CEN/BV-174-C – -176-C, LL/CON/PER/BI-27-C – -30-C, and LL/CON/PER/BV-178-C – -180-C. Updated the TCMT accordingly. (LATER INCORPORATION OF TI27749.) HCI.TS: Incorporated Shorter Connection Intervals Test CR r13 to integrate the Shorter Connection Intervals feature for Core v6.2. Added references to LL and HCI parts of Core v6.2 to the References section; added new TCs HCI/CCO/BI-133-C – -142-C; updated HCI/CCO/BI-63-C with an additional round. Updated the TCMT accordingly. (LATER INCORPORATION OF TI27749 with new TCs HCI/CCO/BI-143-C – 146-C and TI27898 with new TC HCI/CCO/BI-147-C.)
A17: 27815 | B17: CoreTCRL-Validation | C17: TCRL | D17: 2 | E17: Incorporated the validation decision for DEKRA SolutionPRO BEST RF Test System v5.1.0 into the Referenced Test Systems and DEKRA tabs of the TCRL, as well as noting the specific TCIDs on the RFPHY tab.
A18: 27822 | B18: CoreTCRL-Validation | C18: TCRL | D18: 2 | E18: Incorporated the validation decision for MinLian BTS 2.0.0 into the Referenced Test Systems and MinLian tabs of the TCRL, as well as noting the specific TCIDs on the RFPHY tab.
... A156: 27851 | B156: SM | C156: TS, TCMT | D156: 4 | E156: To accommodate E26047, added new TC SM/SIGN/BI-02-C. Updated the TCMT accordingly.

Sheet 80211MP
A1: Test Case Reference List
A2: =Top!C24 -> IEEE 802.11 PHY and MAC Layers | D2: Previous TS | E2: =Top!E24 -> 80211MP.TS.p7 | H2: TS | I2: =Top!G24 -> 80211MP.TS.p7 | J2: Available Date | K2: 45474
A3: =Top!D24 -> IEEE 802.11-2007 (1) | D3: Previous ICS | E3: =Top!F24 -> 80211MP.ICS.p7 | H3: ICS | I3: =Top!H24 -> 80211MP.ICS.p7 | J3: Available Date | K3: 45474
A4: Release date | B4: =rel_date -> 45965
A5: go to top | D5: Previously published test requirements | H5: Updated requirements through this release
A6: TCID*** | B6: Description | C6: TCRL Package Version Last Updated | D6: TC Category | E6: Active Date | F6: Test System Alternatives | G6: Notes | H6: TC Category | I6: Active Date | J6: Test System Alternatives | K6: Notes
A7: TCMT | B7: Test Case Mapping Table | C7: 2024-1 | E7: 45564 | G7: TSE 24025
A8: ICS | B8: Implementation Conformance Statement | C8: 2024-1 | E8: 45564 | G8: TSE 24025
A9: 80211MP/AD/BV-01-C | B9: Duration field zero | D9: B | E9: 45564 | F9: Member Defined
A10: 80211MP/AD/BV-02-C | B10: Duration field non-zero | D10: B | E10: 45564 | F10: Member Defined
A11: 80211MP/AD/BV-03-C | B11: Large duration value | D11: B | E11: 45564 | F11: Member Defined
A12: 80211MP/AD/BI-01-C | B12: FCS validation | D12: B | E12: 45564 | F12: Member Defined
A13: 80211MP/AD/BI-02-C | B13: Non-authenticated source | D13: B | E13: 45564 | F13: Member Defined
A14: 80211MP/ND/BV-01-C | B14: Process properly formatted null data frames | D14: B | E14: 45564 | F14: Member Defined
A15: 80211MP/ND/BI-01-C | B15: Reject improperly formatted null data frames | D15: B | E15: 45564 | F15: Member Defined
A16: 80211MP/RC/BV-01-C | B16: RTS/CTS with proper duration in CTS | D16: B | E16: 45564 | F16: Member Defined
A17: 80211MP/DF/BV-01-C | B17: Receive fragmented frames | D17: B | E17: 45564 | F17: Member Defined
A18: 80211MP/AFP/BI-01-C | B18: authentication frames with failure status code | D18: B | E18: 45564 | F18: Member Defined
A19: 80211MP/AFP/BI-02-C | B19: Authentication Frame Processing - invalid transaction sequence number | D19: B | E19: 45564 | F19: Member Defined
A20: 80211MP/AFP/BI-03-C | B20: authentication frames with invalid algorithm number | D20: B | E20: 45564 | F20: Member Defined
... A60: 80211MP/RT/BV-03-C | B60: IUT retransmits unacknowledged short data frame | D60: B | E60: 45564 | F60: Member Defined
A62: * Any technical changes in this release are indicated in the Notes column.
A63: *** Previous TCIDs of active test cases are listed in the TCID History tab at the end of this workbook.

Sheet 80211PAL
A1: Test Case Reference List
A2: =Top!C9 -> 802.11 PAL Conformance | D2: Previous TS | E2: =Top!E9 -> 80211PAL.TS.p13 | H2: TS | I2: =Top!G9 -> 80211PAL.TS.p13 | J2: Available Date | K2: 45474
A3: =Top!$D$9 -> Vol 5 Part A, 4.2–5.2 | D3: Previous ICS | E3: =Top!F9 -> 80211PAL.ICS.p9 | H3: ICS | I3: =Top!H9 -> 80211PAL.ICS.p9 | J3: Available Date | K3: 45474
A4: =Top!A2 -> Release Date | B4: =rel_date -> 45965
A5: go to top | D5: Previously published test requirements | H5: Updated requirements through this release
A6: TCID*** | B6: Description | C6: TCRL Package Version Last Updated | D6: TC Category | E6: Active Date | F6: Test System Alternatives | G6: Notes | H6: TC Category | I6: Active Date | J6: Test System Alternatives | K6: Notes
A7: TCMT | B7: Test Case Mapping Table | C7: 2024-1 | E7: 45564 | G7: TSE 24026
A8: ICS | B8: Implementation Conformance Statement | C8: 2024-1 | E8: 45564 | G8: TSE 24026
A9: 80211PAL/DI/AI/BV-01-C | B9: Read local AMP info | D9: B | E9: 45564 | F9: Member Defined
A10: 80211PAL/DI/AI/BV-02-C | B10: Read Local AMP Info on HT device, guaranteed logical links not supported | D10: B | E10: 45564 | F10: Member Defined
A11: 80211PAL/DI/AI/BV-03-C | B11: Read Local AMP Info on HT device, guaranteed logical links supported | D11: B | E11: 45564 | F11: Member Defined
A12: 80211PAL/DI/AA/BV-01-C | B12: Read local AMP Assoc, no Physical Link | D12: B | E12: 45564 | F12: Member Defined
A13: 80211PAL/DI/AA/BV-02-C | B13: Write Remote AMP Assoc | D13: B | E13: 45564 | F13: Member Defined
A14: 80211PAL/DI/AA/BI-01-C | B14: Write remote AMP Assoc, unsupported IE token | D14: B | E14: 45564 | F14: Member Defined
A15: 80211PAL/DI/AA/BI-02-C | B15: Read local AMP Assoc, invalid physical link | D15: B | E15: 45564 | F15: Member Defined
A16: 80211PAL/DI/AA/BV-03-C | B16: Read Local AMP Assoc, Activity Reports declared | D16: B | E16: 45564 | F16: Member Defined
A17: 80211PAL/DI/AA/BV-04-C | B17: Read Local AMP Assoc, Activity Report Scheduling supported | D17: B | E17: 45564 | F17: Member Defined
A18: 80211PAL/DI/AA/BV-05-C | B18: Read Local AMP Assoc on HT, 40 MHz channel generation | D18: B | E18: 45564 | F18: Member Defined
A19: 80211PAL/DI/AA/BV-06-C | B19: Write Remote AMP Assoc, 40 MHz channel parsing | D19: B | E19: 45564 | F19: Member Defined
A20: 80211PAL/DI/AA/BI-03-C | B20: Write remote AMP Assoc, invalid length of TLV | D20: B | E20: 45564 | F20: Member Defined
... A68: 80211PAL/OT/SRM/BV-01-C | B68: Short Range Mode | D68: B | E68: 45564 | F68: Member Defined
A70: * Any technical changes in this release are indicated in the Notes column.
A71: *** Previous TCIDs of active test cases are listed in the TCID History tab at the end of this workbook.

Sheet A2MP
A1: Test Case Reference List
A2: =Top!C20 -> AMP Manager Conformance | D2: Previous TS | E2: =Top!E20 -> A2MP.TS.p8 | H2: TS | I2: =Top!G20 -> A2MP.TS.p8 | J2: Available Date | K2: 43493
A3: =Top!$D$20 -> Vol 3 Part E, 4.2–5.2 | D3: Previous ICS | E3: =Top!F20 -> A2MP.ICS.p8 | H3: ICS | I3: =Top!H20 -> A2MP.ICS.p8 | J3: Available Date | K3: 45474
A4: Release date | B4: =rel_date -> 45965
A5: go to top | D5: Previously published test requirements | H5: Updated requirements through this release
A6: TCID*** | B6: Description | C6: TCRL Package Version Last Updated | D6: TC Category | E6: Active Date | F6: Test System Alternatives | G6: Notes | H6: TC Category | I6: Active Date | J6: Test System Alternatives | K6: Notes
A7: TCMT | B7: Test Case Mapping Table | E7: 43583
A8: ICS | B8: Implementation Conformance Statement | C8: 2024-1 | E8: 45564 | G8: TSE 24067
A9: A2MP/RSP/PROT/BV-01-C | B9: Respond to Illegal AMP Command | D9: B | E9: 43583 | F9: Member Defined
A10: A2MP/RSP/PROT/BV-02-C | B10: AMP Discover Request | D10: B | E10: 43583 | F10: Member Defined
A11: A2MP/RSP/PROT/BV-03-C | B11: AMP Discover Response | D11: B | E11: 43583 | F11: Member Defined
A12: A2MP/RSP/PROT/BV-05-C | B12: AMP Change Notify | D12: B | E12: 43583 | F12: Member Defined
A13: A2MP/RSP/PROT/BV-06-C | B13: AMP Change Response | D13: B | E13: 43583 | F13: Member Defined
A14: A2MP/RSP/PROT/BV-07-C | B14: AMP Get Info Request | D14: B | E14: 43583 | F14: Member Defined
A15: A2MP/RSP/PROT/BV-08-C | B15: AMP Get Info Response | D15: B | E15: 43583 | F15: Member Defined
A16: A2MP/RSP/PROT/BV-09-C | B16: AMP Get AMP Assoc Request | D16: B | E16: 43583 | F16: Member Defined
A17: A2MP/RSP/PROT/BV-10-C | B17: AMP Get AMP Assoc Response | D17: B | E17: 43583 | F17: Member Defined
A18: A2MP/RSP/PROT/BV-11-C | B18: AMP Get Info Request containing unsupported AMP ID | D18: B | E18: 43583 | F18: Member Defined
A19: A2MP/RSP/PROT/BV-12-C | B19: AMP Get AMP Assoc Request containing unsupported AMP ID | D19: B | E19: 43583 | F19: Member Defined
A20: A2MP/RSP/PROT/BV-13-C | B20: Extended Feature Mask Extension in AMP Discover Request | D20: B | E20: 43583 | F20: Member Defined
... A36: A2MP/RSP/SEC/BV-03-C | B36: Successful Initiation of Physical Link - Change of BR/EDR Link Key - IUT as Initiator | D36: B | E36: 43583 | F36: Member Defined
A37: A2MP/RSP/SEC/BV-04-C | B37: No longer used | C37: 2021-1
A38: A2MP/RSP/SEC/BV-05-C | B38: Unsuccessful Initiation of Physical Link version 1 - Retry - IUT as Initiator | D38: B | E38: 43583 | F38: Member Defined
A39: A2MP/RSP/SEC/BV-06-C | B39: No longer used | C39: 2021-1
A40: A2MP/RSP/SEC/BV-07-C | B40: Unsuccessful Initiation of Physical Link version 2 - Retry - IUT is Initiator | D40: B | E40: 43583 | F40: Member Defined
A41: A2MP/RSP/SEC/BV-08-C | B41: No longer used | C41: 2021-1
A42: A2MP/RSP/SEC/BV-09-C | B42: Successful Initiation of Physical Link - Reconnection - IUT is Responder | D42: B | E42: 43583 | F42: Member Defined
A43: A2MP/RSP/SEC/BV-10-C | B43: Successful Initiation of Physical Link - Repairing - IUT as Responder | D43: B | E43: 43583 | F43: Member Defined
A44: A2MP/RSP/SEC/BV-11-C | B44: No longer used | C44: 2021-1
A45: A2MP/RSP/SEC/BV-12-C | B45: Unsuccessful Initiation of Physical Link version 1 - Retry - IUT as Responder | D45: B | E45: 43583 | F45: Member Defined
A46: A2MP/RSP/SEC/BV-13-C | B46: No longer used | C46: 2021-1
A47: A2MP/RSP/SEC/BV-14-C | B47: Unsuccessful Initiation of Physical Link version 2 - Retry - IUT is Responder | D47: B | E47: 43583 | F47: Member Defined
A48: A2MP/RSP/SEC/BV-15-C | B48: No longer used | C48: 2021-1
A50: * Any technical changes in this release are indicated in the Notes column.
A51: *** Previous TCIDs of active test cases are listed in the TCID History tab at the end of this workbook.

Sheet BB
A1: Test Case Reference List
A2: =Top!C6 -> Baseband Conformance | D2: Previous TS | E2: =Top!E6 -> BB.TS.p38 | H2: TS | I2: =Top!G6 -> BB.TS.p39 | J2: Available Date | K2: =rel_date -> 45965
A3: =Top!D6 -> Vol 2 Part B, 4.2–6.2 | D3: Previous ICS | E3: =Top!F6 -> BB.ICS.p27 | H3: ICS | I3: =Top!H6 -> BB.ICS.p28 | J3: Available Date | K3: =rel_date -> 45965
A4: =Top!A2 -> Release Date | B4: =Top!$B$2 -> 45965
A5: go to top | D5: Previously published test requirements | H5: Updated requirements through this release
A6: TCID*** | B6: Description | C6: TCRL Package Version Last Updated | D6: TC Category | E6: Active Date | F6: Test System Alternatives | G6: Notes | H6: TC Category | I6: Active Date | J6: Test System Alternatives | K6: Notes
A7: TCMT | B7: Test Case Mapping Table | C7: pkg101 | E7: 45873 | G7: TSE 26887 | I7: =$B$4+90 -> 46055 | K7: TSE 27200
A8: ICS | B8: Implementation Conformance Statement | C8: pkg101 | E8: 45629 | I8: =$B$4+90 -> 46055 | K8: TSEs 26825, 27061, 27209
A9: BB/PHYS/FRE/BV-01-C | B9: 79 Channel Hop Seq | D9: A | E9: 45873 | F9: 15) | H9: A | I9: =$B$4+90 -> 46055 | J9: 15)
A10: BB/PHYS/FRE/BV-02-C | B10: AFH Hop Seq | D10: A | E10: 45873 | F10: 15) | H10: A | I10: =$B$4+90 -> 46055 | J10: 15)
A11: BB/PHYS/FRE/BV-03-C | B11: AFH Hop Seq after Role Switch | D11: A | E11: 45873 | F11: 15) | H11: A | I11: =$B$4+90 -> 46055 | J11: 15)
A12: BB/PHYS/INQ/BV-01-C | B12: Inquiry Hop Sequence | D12: A | E12: 45873 | F12: 15) | H12: A | I12: =$B$4+90 -> 46055 | J12: 15)
A13: BB/PHYS/INQ/BV-03-C | B13: Inquiry Proc | D13: A | E13: 45873 | F13: 15) | H13: A | I13: =$B$4+90 -> 46055 | J13: 15)
A14: BB/PHYS/INQ/BV-10-C | B14: Inquiry Response | D14: A | E14: 45873 | F14: 15) | H14: A | I14: =$B$4+90 -> 46055 | J14: 15)
A15: BB/PHYS/INQ/BV-14-C | B15: Inquiry Scan Window and Interval | D15: A | E15: 45873 | F15: 15) | H15: A | I15: =$B$4+90 -> 46055 | J15: 15)
A16: BB/PHYS/INQ/BV-15-C | B16: Interlaced Inquiry Scan Window and Interval | D16: A | E16: 45873 | F16: 15) | H16: A | I16: =$B$4+90 -> 46055 | J16: 15)
A17: BB/PHYS/INQ/BV-16-C | B17: Reception of Extended Inquiry Response | D17: A | E17: 45873 | F17: 15) | H17: A | I17: =$B$4+90 -> 46055 | J17: 15)
A18: BB/PHYS/INQ/BV-17-C | B18: Transmission of Extended Inquiry Response | D18: A | E18: 45873 | F18: 15) | H18: A | I18: =$B$4+90 -> 46055 | J18: 15)
A19: BB/PHYS/INQ/BV-18-C | B19: Inquiry Result Event Usage | D19: A | E19: 45873 | F19: 15) | H19: A | I19: =$B$4+90 -> 46055 | J19: 15)
A20: BB/PHYS/INQ/BV-19-C | B20: Inquiry Hop Sequence with Train Nudge | D20: A | E20: 45873 | F20: 15) | H20: A | I20: =$B$4+90 -> 46055 | J20: 15)
A21: BB/PHYS/INQ/BV-20-C | B21: Generalized Interlaced Inquiry Scan | D21: A | E21: 45873 | F21: 15) | H21: A | I21: =$B$4+90 -> 46055 | J21: 15)
A22: BB/PHYS/PAG/BI-01-C | B22: Ignore Page from Central using the IUT address | C22: 2024-2 | D22: A | E22: 45873 | F22: 15) | H22: A | I22: =$B$4+90 -> 46055 | J22: 15)
A23: BB/PHYS/PAG/BV-01-C | B23: Page Hop Seq | D23: A | E23: 45873 | F23: 15) | H23: A | I23: =$B$4+90 -> 46055 | J23: 15)
A24: BB/PHYS/PAG/BV-03-C | B24: Page Response to 1st Message | D24: A | E24: 45873 | F24: 15) | H24: A | I24: =$B$4+90 -> 46055 | J24: 15)
A25: BB/PHYS/PAG/BV-05-C | B25: Page Response to 2nd Message | D25: A | E25: 45873 | F25: 15) | H25: A | I25: =$B$4+90 -> 46055 | J25: 15)
A26: BB/PHYS/PAG/BV-10-C | B26: Page Response 1/1 Slot | D26: A | E26: 45873 | F26: 15) | H26: A | I26: =$B$4+90 -> 46055 | J26: 15)
A27: BB/PHYS/PAG/BV-12-C | B27: Page Response 1/2 slot | D27: A | E27: 45873 | F27: 15) | H27: A | I27: =$B$4+90 -> 46055 | J27: 15)
A28: BB/PHYS/PAG/BV-14-C | B28: Page Scan Interval R0 | D28: A | E28: 45873 | F28: 15) | H28: A | I28: =$B$4+90 -> 46055 | J28: 15)
A29: BB/PHYS/PAG/BV-16-C | B29: Page Scan Interval R1 | D29: A | E29: 45873 | F29: 15) | H29: A | I29: =$B$4+90 -> 46055 | J29: 15)
A30: BB/PHYS/PAG/BV-17-C | B30: Page Scan Interval R1 with Interlaced Scan | D30: A | E30: 45873 | F30: 15) | H30: A | I30: =$B$4+90 -> 46055 | J30: 15)
A31: BB/PHYS/PAG/BV-18-C | B31: Page Scan Interval R2 | D31: A | E31: 45873 | F31: 15) | H31: A | I31: =$B$4+90 -> 46055 | J31: 15)
A32: BB/PHYS/PAG/BV-19-C | B32: Page Scan Interval R2 and Interlaced Scan | D32: A | E32: 45873 | F32: 15) | H32: A | I32: =$B$4+90 -> 46055 | J32: 15)
A33: BB/PHYS/PAG/BV-20-C | B33: Page Hop Sequence with Train Nudge | D33: A | E33: 45873 | F33: 15) | H33: A | I33: =$B$4+90 -> 46055 | J33: 15)
A34: BB/PHYS/PAG/BV-21-C | B34: Generalized Interlaced Page Scan | D34: A | E34: 45873 | F34: 15) | H34: A | I34: =$B$4+90 -> 46055 | J34: 15)
... A45: BB/PHYS/TRX/BV-04-C | B45: Peripheral RX/TX Timing | D45: A | E45: 45873 | F45: 15) | H45: A | I45: =$B$4+90 -> 46055 | J45: 15)
A46: BB/PHYS/TRX/BV-05-C to -07-C | B46: No longer used
A47: BB/PROT/ARQ/BV-01-C | B47: Explicit NAK | D47: A | E47: 45873 | F47: 15) | H47: A | I47: =$B$4+90 -> 46055 | J47: 15)
A48: BB/PROT/ARQ/BV-02-C | B48: Implicit NAK | D48: A | E48: 45873 | F48: 15) | H48: A | I48: =$B$4+90 -> 46055 | J48: 15)
A49: BB/PROT/ARQ/BV-03-C | B49: Uncorrectable Packet Header | D49: A | E49: 45873 | F49: 15) | H49: A | I49: =$B$4+90 -> 46055 | J49: 15)
A50: BB/PROT/ARQ/BV-04-C | B50: Uncorrectable Payload | D50: A | E50: 45873 | F50: 15) | H50: A | I50: =$B$4+90 -> 46055 | J50: 15)
...

Sheet CS
A1: Test Case Reference List
A2: =Top!C14 -> Channel Sounding Conformance | D2: Previous TS | E2: =Top!E14 -> CS.TS.p2 | H2: TS | I2: =Top!G14 -> CS.TS.p3 | J2: Available Date | K2: =rel_date -> 45965
A3: =Top!D14 -> Vol 6 Part H, 6.0–6.2 | D3: Previous ICS | E3: =Top!F14 -> CS.ICS.p2 | H3: ICS | I3: =Top!H14 -> CS.ICS.p3 | J3: Available Date | K3: =rel_date -> 45965
A4: =Top!A2 -> Release Date | B4: =Top!$B$2 -> 45965
A5: go to top | D5: Previously published test requirements | H5: Updated requirements through this release
A6: TCID*** | B6: Description | C6: TCRL Package Version Last Updated | D6: TC Category | E6: Active Date | F6: Test System Alternatives | G6: Notes | H6: TC Category | I6: Active Date | J6: Test System Alternatives | K6: Notes
A7: TCMT | B7: Test Case Mapping Table | C7: pkg101 | E7: 45873 | G7: TSE 27418 | I7: =$B$4+90 -> 46055 | K7: TSE 27907 (CSAA) TSE 27591
A8: ICS | B8: Implementation Conformance Statement | C8: pkg101 | E8: 45873 | G8: TSE 26663 | I8: =$B$4+90 -> 46055 | K8: TSE 27907 (CSAA)
A9: CS/NAD/INI/BV-01-C | B9: Phase-Based Normalized Attack Detector Metric, Mode-1, Random Sequence 32-bits, Initiator LE 1M PHY | C9: 2024-2 | D9: B | E9: 45873 | F9: Member Defined | H9: B | I9: =$B$4+90 -> 46055 | J9: Member Defined
A10: CS/NAD/INI/BV-02-C | B10: Phase-Based Normalized Attack Detector Metric, Mode-1, Random Sequence 64-bits, Initiator LE 1M PHY | C10: 2024-2 | D10: B | E10: 45873 | F10: Member Defined | H10: B | I10: =$B$4+90 -> 46055 | J10: Member Defined
A11: CS/NAD/INI/BV-03-C | B11: Phase-Based Normalized Attack Detector Metric, Mode-1, Random Sequence 96-bits, Initiator LE 1M PHY | C11: 2024-2 | D11: B | E11: 45873 | F11: Member Defined | H11: B | I11: =$B$4+90 -> 46055 | J11: Member Defined
A12: CS/NAD/INI/BV-04-C | B12: Phase-Based Normalized Attack Detector Metric, Mode-1, Random Sequence 128-bits, Initiator LE 1M PHY | C12: 2024-2 | D12: B | E12: 45873 | F12: Member Defined | H12: B | I12: =$B$4+90 -> 46055 | J12: Member Defined
A13: CS/NAD/INI/BV-05-C | B13: Phase-Based Normalized Attack Detector Metric, Mode-1, Sounding Sequence 32-bits, Initiator LE 1M PHY | C13: 2024-2 | D13: B | E13: 45873 | F13: Member Defined | H13: B | I13: =$B$4+90 -> 46055 | J13: Member Defined
A14: CS/NAD/INI/BV-06-C | B14: Phase-Based Normalized Attack Detector Metric, Mode-1, Sounding Sequence 96-bits, Initiator LE 1M PHY | C14: 2024-2 | D14: B | E14: 45873 | F14: Member Defined | H14: B | I14: =$B$4+90 -> 46055 | J14: Member Defined
A15: CS/NAD/INI/BV-07-C | B15: Phase-Based Normalized Attack Detector Metric, Mode-3, Random Sequence 32-bits, Initiator LE 1M PHY | C15: 2024-2 | D15: B | E15: 45873 | F15: Member Defined | H15: B | I15: =$B$4+90 -> 46055 | J15: Member Defined
A16: CS/NAD/INI/BV-08-C | B16: Phase-Based Normalized Attack Detector Metric, Mode-3, Random Sequence 64-bits, Initiator LE 1M PHY | C16: 2024-2 | D16: B | E16: 45873 | F16: Member Defined | H16: B | I16: =$B$4+90 -> 46055 | J16: Member Defined
A17: CS/NAD/INI/BV-09-C | B17: Phase-Based Normalized Attack Detector Metric, Mode-3, Random Sequence 96-bits, Initiator LE 1M PHY | C17: 2024-2 | D17: B | E17: 45873 | F17: Member Defined | H17: B | I17: =$B$4+90 -> 46055 | J17: Member Defined
A18: CS/NAD/INI/BV-10-C | B18: Phase-Based Normalized Attack Detector Metric, Mode-3, Random Sequence 128-bits, Initiator LE 1M PHY | C18: 2024-2 | D18: B | E18: 45873 | F18: Member Defined | H18: B | I18: =$B$4+90 -> 46055 | J18: Member Defined
A19: CS/NAD/INI/BV-11-C | B19: Phase-Based Normalized Attack Detector Metric, Mode-3, Sounding Sequence 32-bits, Initiator LE 1M PHY | C19: 2024-2 | D19: B | E19: 45873 | F19: Member Defined | H19: B | I19: =$B$4+90 -> 46055 | J19: Member Defined
A20: CS/NAD/INI/BV-12-C | B20: Phase-Based Normalized Attack Detector Metric, Mode-3, Sounding Sequence 96-bits, Initiator LE 1M PHY | C20: 2024-2 | D20: B | E20: 45873 | F20: Member Defined | H20: B | I20: =$B$4+90 -> 46055 | J20: Member Defined
... A80: CS/NAD/REF/BV-36-C | B80: Phase-Based Normalized Attack Detector Metric, Mode-3, Sounding Sequence 96-bits, Reflector LE 2M 2BT PHY | C80: 2024-2 | D80: B | E80: 45873 | F80: Member Defined | H80: B | I80: =$B$4+90 -> 46055 | J80: Member Defined
A81: CS/NAD/REF/BV-37-C | B81: Amplitude-based Attack Resilience NADM, Mode-1, Random Sequence, LE 1M PHY | C81: pkg101 | H81: B | I81: =$B$4+0 -> 45965 | J81: Member Defined | K81: TSE 27907 (CSAA), new TC
A82: CS/NAD/REF/BV-38-C | B82: Amplitude-based Attack Resilience NADM, Mode-1, Sounding Sequence, LE 1M PHY | C82: pkg101 | H82: B | I82: =$B$4+0 -> 45965 | J82: Member Defined | K82: TSE 27907 (CSAA), new TC
A83: CS/NAD/REF/BV-39-C | B83: Amplitude-based Attack Resilience NADM, Mode-3, Random Sequence, LE 1M PHY | C83: pkg101 | H83: B | I83: =$B$4+0 -> 45965 | J83: Member Defined | K83: TSE 27907 (CSAA), new TC
A84: CS/NAD/REF/BV-40-C | B84: Amplitude-based Attack Resilience NADM, Mode-3, Sounding Sequence, LE 1M PHY | C84: pkg101 | H84: B | I84: =$B$4+0 -> 45965 | J84: Member Defined | K84: TSE 27907 (CSAA), new TC
A85: CS/NAD/REF/BV-41-C | B85: Amplitude-based Attack Resilience NADM, Mode-1, Random Sequence, LE 2M PHY | C85: pkg101 | H85: B | I85: =$B$4+0 -> 45965 | J85: Member Defined | K85: TSE 27907 (CSAA), new TC
A86: CS/NAD/REF/BV-42-C | B86: Amplitude-based Attack Resilience NADM, Mode-1, Sounding Sequence, LE 2M PHY | C86: pkg101 | H86: B | I86: =$B$4+0 -> 45965 | J86: Member Defined | K86: TSE 27907 (CSAA), new TC
A87: CS/NAD/REF/BV-43-C | B87: Amplitude-based Attack Resilience NADM, Mode-3, Random Sequence, LE 2M PHY | C87: pkg101 | H87: B | I87: =$B$4+0 -> 45965 | J87: Member Defined | K87: TSE 27907 (CSAA), new TC
A88: CS/NAD/REF/BV-44-C | B88: Amplitude-based Attack Resilience NADM, Mode-3, Sounding Sequence, LE 2M PHY | C88: pkg101 | H88: B | I88: =$B$4+0 -> 45965 | J88: Member Defined | K88: TSE 27907 (CSAA), new TC
A89: CS/NAD/REF/BV-45-C | B89: Amplitude-based Attack Resilience NADM, Mode-1, Random Sequence, LE 2M 2BT PHY | C89: pkg101 | H89: B | I89: =$B$4+0 -> 45965 | J89: Member Defined | K89: TSE 27907 (CSAA), new TC
A90: CS/NAD/REF/BV-46-C | B90: Amplitude-based Attack Resilience NADM, Mode-1, Sounding Sequence, LE 2M 2BT PHY | C90: pkg101 | H90: B | I90: =$B$4+0 -> 45965 | J90: Member Defined | K90: TSE 27907 (CSAA), new TC
A91: CS/NAD/REF/BV-47-C | B91: Amplitude-based Attack Resilience NADM, Mode-3, Random Sequence, LE 2M 2BT PHY | C91: pkg101 | H91: B | I91: =$B$4+0 -> 45965 | J91: Member Defined | K91: TSE 27907 (CSAA), new TC
A92: CS/NAD/REF/BV-48-C | B92: Amplitude-based Attack Resilience NADM, Mode-3, Sounding Sequence, LE 2M 2BT PHY | C92: pkg101 | H92: B | I92: =$B$4+0 -> 45965 | J92: Member Defined | K92: TSE 27907 (CSAA), new TC
A93: CS/PAC/INI/BV-01-C | B93: Sounding Sequence, Marker Signals, Initiator, LE 1M, Mode-1 32-bit | C93: pkg101 | D93: A | E93: 45873 | F93: 15) | H93: A | I93: =$B$4+90 -> 46055 | J93: 15), 20) | K93: TSE 26167
A94: CS/PAC/INI/BV-02-C | B94: Sounding Sequence, Marker Signals, Initiator, LE 2M, Mode-1 32-bit | C94: pkg101 | D94: A | E94: 45873 | F94: 15) | H94: A | I94: =$B$4+90 -> 46055 | J94: 15) | K94: TSE 26167
A95: CS/PAC/INI/BV-03-C | B95: Sounding Sequence, Marker Signals, Initiator, LE 1M, Mode-1 96-bit | C95: pkg101 | D95: A | E95: 45873 | F95: 15) | H95: A | I95: =$B$4+90 -> 46055 | J95: 15), 20) | K95: TSE 26167
A96: CS/PAC/INI/BV-04-C | B96: Sounding Sequence, Marker Signals, Initiator, LE 2M, Mode-1 96-bit | C96: pkg101 | D96: A | E96: 45873 | F96: 15) | H96: A | I96: =$B$4+90 -> 46055 | J96: 15) | K96: TSE 26167
A97: CS/PAC/INI/BV-05-C | B97: Sounding Sequence, Marker Signals, Initiator, LE 1M, Mode-3 32-bit | C97: pkg101 | D97: A | E97: 45873 | F97: 15) | H97: A | I97: =$B$4+90 -> 46055 | J97: 15) | K97: TSE 26167
A98: CS/PAC/INI/BV-06-C | B98: Sounding Sequence, Marker Signals, Initiator, LE 2M, Mode-3 32-bit | C98: pkg101 | D98: A | E98: 45873 | F98: 15) | H98: A | I98: =$B$4+90 -> 46055 | J98: 15) | K98: TSE 26167
A99: CS/PAC/INI/BV-07-C | B99: Sounding Sequence, Marker Signals, Initiator, LE 1M, Mode-3 96-bit | C99: pkg101 | D99: A | E99: 45873 | F99: 15) | H99: A | I99: =$B$4+90 -> 46055 | J99: 15) | K99: TSE 26167
...

Sheet GAP
A1: Test Case Reference List
A2: Generic Access Profile Conformance | D2: Previous TS | E2: =Top!E19 -> GAP.TS.p48 | H2: TS | I2: =Top!G19 -> GAP.TS.p49 | J2: Available Date | K2: =rel_date -> 45965
A3: =Top!D19 -> Vol 3 Part C, 4.2–6.2 | D3: Previous ICS | E3: =Top!F19 -> GAP.ICS.p44 | H3: ICS | I3: =Top!H19 -> GAP.ICS.p45 | J3: Available Date | K3: =rel_date -> 45965
A4: Release date | B4: =rel_date -> 45965
A5: go to top | D5: Previously published test requirements | H5: Updated Requirements through this release
A6: TCID*** | B6: Description | C6: TCRL Package Version Last Updated | D6: TC Category | E6: Active Date | F6: Test System Alternatives | G6: Notes | H6: TC Category | I6: Active Date | J6: Test System Alternatives | K6: Notes
A7: TCMT | B7: Test Case Mapping Table | C7: pkg101 | E7: 45873 | G7: TSEs 18571, 26034, 26461, 26582, 26734 | I7: =$B$4+90 -> 46055 | K7: TSEs 27212, 27259, 27704
A8: ICS | B8: Implementation Conformance Statement | C8: pkg101 | E8: 45873 | G8: TSEs 18571, 26034, 26582, 26641, 26642, 27042 | I8: =$B$4+90 -> 46055 | K8: TSEs 26830, 27259, 27903
A9: GAP/ADV/BV-01-C | B9: AD type – Service UUID | C9: 2022-2 | D9: B | E9: 45873 | F9: 10) | H9: B | I9: =$B$4+90 -> 46055 | J9: 10)
A10: GAP/ADV/BV-02-C | B10: AD type – Local Name | C10: 2022-2 | D10: B | E10: 45873 | F10: 10) | H10: B | I10: =$B$4+90 -> 46055 | J10: 10)
A11: GAP/ADV/BV-03-C | B11: AD type – Flags | C11: 2022-2 | D11: B | E11: 45873 | F11: 10) | H11: B | I11: =$B$4+90 -> 46055 | J11: 10)
A12: GAP/ADV/BV-04-C | B12: AD type – Manufacturer Specific Data | C12: 2022-2 | D12: A | E12: 45873 | F12: 18) | H12: A | I12: =$B$4+90 -> 46055 | J12: 18)
A13: GAP/ADV/BV-05-C | B13: AD type – TX Power Level | C13: 2022-2 | D13: A | E13: 45873 | F13: 18) | H13: A | I13: =$B$4+90 -> 46055 | J13: 18)
A14: GAP/ADV/BV-08-C | B14: AD type – Peripheral Connection Interval Range | C14: 2022-2 | D14: A | E14: 45873 | F14: 18) | H14: A | I14: =$B$4+90 -> 46055 | J14: 18)
A15: GAP/ADV/BV-09-C | B15: AD type – Service Solicitation | C15: 2022-2 | D15: A | E15: 45873 | F15: 10) | H15: A | I15: =$B$4+90 -> 46055 | J15: 10)
A16: GAP/ADV/BV-10-C | B16: AD type – Service Data | C16: 2022-2 | D16: B | E16: 45873 | F16: 10) | H16: B | I16: =$B$4+90 -> 46055 | J16: 10)
A17: GAP/ADV/BV-11-C | B17: AD type – Appearance | C17: 2022-2 | D17: B | E17: 45873 | F17: 10) | H17: B | I17: =$B$4+90 -> 46055 | J17: 10)
A18: GAP/ADV/BV-12-C | B18: AD type – Public Target Address | C18: 2022-2 | D18: A | E18: 45873 | F18: 18) | H18: A | I18: =$B$4+90 -> 46055 | J18: 18)
A19: GAP/ADV/BV-13-C | B19: AD type – Random Target Address | C19: 2022-2 | D19: A | E19: 45873 | F19: 10) | H19: A | I19: =$B$4+90 -> 46055 | J19: 10)
A20: GAP/ADV/BV-14-C | B20: AD type – Advertising Interval | C20: 2022-2 | D20: A | E20: 45873 | F20: 18) | H20: A | I20: =$B$4+90 -> 46055 | J20: 18)
A21: GAP/ADV/BV-15-C to BV-16-C | B21: No longer used | C21: 2019-2
A22: GAP/ADV/BV-17-C | B22: AD type – URI | C22: 2022-2 | D22: B | E22: 45873 | F22: Member Defined | H22: B | I22: =$B$4+90 -> 46055 | J22: Member Defined
A23: GAP/ADV/BV-18-C | B23: AD type – Advertising Interval, Long | C23: 2022-2 | D23: B | E23: 45873 | F23: Member Defined | H23: B | I23: =$B$4+90 -> 46055 | J23: Member Defined
A24: GAP/ADV/BV-19-C | B24: AD type – LE Supported Features | C24: 2022-2 | D24: B | E24: 45873 | F24: Member Defined | H24: B | I24: =$B$4+90 -> 46055 | J24: Member Defined
A25: GAP/ADV/BV-20-C | B25: AD type – Encrypted Data | C25: pkg101 | D25: B | E25: 45873 | F25: Member Defined | H25: B | I25: =$B$4+90 -> 46055 | J25: Member Defined | K25: TSE 27704
A26: GAP/ADV/BV-21-C | B26: AD type – Encrypted Data | C26: pkg101 | H26: B | I26: =$B$4+180 -> 46145 | J26: Member Defined | K26: TSE 27704 (new TC)
A27: GAP/BIS/BBM/BV-01-C | B27: Broadcast Isochronous Stream Broadcasting mode | C27: 2019-2 | D27: B | E27: 45873 | F27: Member Defined | H27: B | I27: =$B$4+90 -> 46055 | J27: Member Defined
A28: GAP/BIS/BSE/BV-01-C | B28: Broadcast Isochronous Synchronization Establishment procedure | C28: 2019-2 | D28: B | E28: 45873 | F28: Member Defined | H28: B | I28: =$B$4+90 -> 46055 | J28: Member Defined
A29: GAP/BOND/BON/BV-01-C | B29: Initiate bonding – Peripheral role | C29: 2021-1 | D29: A | E29: 45873 | F29: 11) | H29: A | I29: =$B$4+90 -> 46055 | J29: 11)
A30: GAP/BOND/BON/BV-02-C | B30: Initiate bonding – Central role | C30: 2021-1 | D30: A | E30: 45873 | F30: 13) | H30: A | I30: =$B$4+90 -> 46055 | J30: 13)
A31: GAP/BOND/BON/BV-03-C | B31: Respond to bonding – Peripheral role | C31: 2021-1 | D31: A | E31: 45873 | F31: 10) | H31: A | I31: =$B$4+90 -> 46055 | J31: 10)
A32: GAP/BOND/BON/BV-04-C | B32: Respond to bonding – Central role | C32: 2021-1 | D32: A | E32: 45873 | F32: 19) | H32: A | I32: =$B$4+90 -> 46055 | J32: 19)
A33: GAP/BOND/NBON/BV-01-C | B33: Non-bondable mode – Central as Responder | D33: A | E33: 45873 | F33: 19) | H33: A | I33: =$B$4+90 -> 46055 | J33: 19)
A34: GAP/BOND/NBON/BV-02-C | B34: Non-bondable mode – Central as Initiator | D34: A | E34: 45873 | F34: 19) | H34: A | I34: =$B$4+90 -> 46055 | J34: 19)
A35: GAP/BOND/NBON/BV-03-C | B35: Non-bondable mode – Peripheral as Responder | D35: A | E35: 45873 | F35: 19) | H35: A | I35: =$B$4+90 -> 46055 | J35: 19)
A36: GAP/BROB/BCST/BV-01-C | B36: Broadcast mode, No Scan Response | D36: A | E36: 45873 | F36: 18) | H36: A | I36: =$B$4+90 -> 46055 | J36: 18)
A37: GAP/BROB/BCST/BV-02-C | B37: Broadcast mode, Scan Response | D37: A | E37: 45873 | F37: 18) | H37: A | I37: =$B$4+90 -> 46055 | J37: 18)
A38: GAP/BROB/BCST/BV-03-C | B38: Broadcast mode, Resolvable Private Address | D38: A | E38: 45873 | F38: 16) | H38: A | I38: =$B$4+90 -> 46055 | J38: 16)
A39: GAP/BROB/BCST/BV-04-C | B39: Broadcast mode, Non-Resolvable Private Address | D39: A | E39: 45873 | F39: 11) | H39: A | I39: =$B$4+90 -> 46055 | J39: 11)
A40: GAP/BROB/BCST/BV-05-C | B40: Broadcast mode, Resolvable Private Address, Scan Response | D40: B | E40: 45873 | F40: Member Defined | H40: B | I40: =$B$4+90 -> 46055 | J40: Member Defined
...

Sheet ATT-GATT
A1: Test Case Reference List
A2: Attribute Protocol Conformance
A3: Generic Attribute Profile Conformance | D3: Previous TS | E3: =Top!E22 -> GATT.TS.p28 | H3: TS | I3: =Top!G21 -> GATT.TS.p29 | J3: Available Date | K3: =rel_date -> 45965
A4: =Top!D22 -> Vol 3 Part G, 4.2–6.2 | D4: Previous ICS | E4: =Top!F22 -> GATT.ICS.p21 | H4: ICS | I4: =Top!H22 -> GATT.ICS.p22 | J4: Available Date | K4: =rel_date -> 45965
A5: Release date | B5: =rel_date -> 45965 | D5: Previous ICS | E5: =Top!F21 -> ATT.ICS.p14 | H5: ICS | I5: =Top!H21 -> ATT.ICS.p15 | J5: Available Date | K5: =rel_date -> 45965
A6: go to top | D6: Previously published test requirements | H6: Updated requirements through this release
A7: TCID*** | B7: Description | C7: TCRL Package Version Last Updated | D7: GATT TC Category | E7: Active Date | F7: Test System Alternatives | G7: Notes | H7: GATT TC Category | I7: Active Date | J7: Test System Alternatives | K7: Notes
A8: TCMT | B8: Test Case Mapping Table | C8: pkg101 | E8: 45873 | G8: TSE 24898 | I8: =$B$5+90 -> 46055 | K8: TSE 26905
A9: GATT ICS | B9: Implementation Conformance Statement | C9: pkg101 | E9: 45873 | G9: TSE 25608 | I9: =$B$5+90 -> 46055 | K9: TSEs 26905, 27527, 28196
A10: ATT ICS | B10: Implementation Conformance Statement | C10: pkg101 | E10: 45796 | I10: =$B$5+90 -> 46055 | K10: TSE 27575
A11: GATT/CL/GAC/BV-01-C | B11: Server Configuration - by Client | D11: B | E11: 45873 | F11: Member Defined | H11: B | I11: =$B$5+90 -> 46055 | J11: Member Defined
A12: GATT/CL/GAD/BV-01-C | B12: Discover All Primary Services - by Client | D12: B | E12: 45873 | F12: Member Defined | H12: B | I12: =$B$5+90 -> 46055 | J12: Member Defined
A13: GATT/CL/GAD/BV-02-C | B13: Discover Primary Service by Service UUID – by Client | D13: B | E13: 45873 | F13: Member Defined | H13: B | I13: =$B$5+90 -> 46055 | J13: Member Defined
A14: GATT/CL/GAD/BV-03-C | B14: Find Included Services - by Client | D14: B | E14: 45873 | F14: Member Defined | H14: B | I14: =$B$5+90 -> 46055 | J14: Member Defined
A15: GATT/CL/GAD/BV-04-C | B15: Discover All Characteristics of a Service - by Client | D15: B | E15: 45873 | F15: Member Defined | H15: B | I15: =$B$5+90 -> 46055 | J15: Member Defined
A16: GATT/CL/GAD/BV-05-C | B16: Discover Characteristics by UUID - by Client | D16: B | E16: 45873 | F16: Member Defined | H16: B | I16: =$B$5+90 -> 46055 | J16: Member Defined
A17: GATT/CL/GAD/BV-06-C | B17: Discover All Characteristic Descriptors - by Client | D17: B | E17: 45873 | F17: Member Defined | H17: B | I17: =$B$5+90 -> 46055 | J17: Member Defined
A18: GATT/CL/GAD/BV-07-C | B18: Discover Primary Services using SDP - by Client | C18: 2024-1 | D18: B | E18: 45873 | F18: Member Defined | H18: B | I18: =$B$5+90 -> 46055 | J18: Member Defined
A19: GATT/CL/GAD/BV-08-C | B19: Discover Services by UUID using SDP - by Client | C19: 2024-1 | D19: B | E19: 45873 | F19: Member Defined | H19: B | I19: =$B$5+90 -> 46055 | J19: Member Defined
A20: GATT/CL/GAI/BI-01-C | B20: Multiple Characteristic Value Indication Requests, Client | C20: 2021-1 | D20: B | E20: 45873 | F20: Member Defined | H20: B | I20: =$B$5+90 -> 46055 | J20: Member Defined
A21: GATT/CL/GAI/BV-01-C | B21: Confirm Characteristic Value Indication - by Client | C21: 2019-1 | D21: B | E21: 45873 | F21: Member Defined | H21: B | I21: =$B$5+90 -> 46055 | J21: Member Defined
A22: GATT/CL/GAN/BV-01-C | B22: Characteristic Value Notification - to Client | C22: 2019-1 | D22: B | E22: 45873 | F22: Member Defined | H22: B | I22: =$B$5+90 -> 46055 | J22: Member Defined
A23: GATT/CL/GAN/BV-02-C | B23: Handle Value Multiple Notification - to Client | C23: 2019-2 | D23: B | E23: 45873 | F23: Member Defined | H23: B | I23: =$B$5+90 -> 46055 | J23: Member Defined
A24: GATT/CL/GAR/BI-01-C | B24: Read Characteristic Value - Invalid Handle | D24: B | E24: 45873 | F24: Member Defined | H24: B | I24: =$B$5+90 -> 46055 | J24: Member Defined
A25: GATT/CL/GAR/BI-02-C | B25: Read Characteristic Value - Read Not Permitted | D25: B | E25: 45873 | F25: Member Defined | H25: B | I25: =$B$5+90 -> 46055 | J25: Member Defined
A26: GATT/CL/GAR/BI-03-C | B26: Read Characteristic Value - Insufficient Authorization | C26: 2019-1 | D26: B | E26: 45873 | F26: Member Defined | H26: B | I26: =$B$5+90 -> 46055 | J26: Member Defined
A27: GATT/CL/GAR/BI-04-C | B27: Read Characteristic Value - Insufficient Authentication | C27: 2019-1 | D27: B | E27: 45873 | F27: Member Defined | H27: B | I27: =$B$5+90 -> 46055 | J27: Member Defined
A28: GATT/CL/GAR/BI-05-C | B28: Read Characteristic Value - Insufficient Encryption Key Size | C28: 2019-1 | D28: B | E28: 45873 | F28: Member Defined | H28: B | I28: =$B$5+90 -> 46055 | J28: Member Defined
A29: GATT/CL/GAR/BI-06-C | B29: Read Using Characteristic UUID - Read Not Permitted | D29: B | E29: 45873 | F29: Member Defined | H29: B | I29: =$B$5+90 -> 46055 | J29: Member Defined
A30: GATT/CL/GAR/BI-07-C | B30: Read Using Characteristic UUID - Attribute Not Found | D30: B | E30: 45873 | F30: Member Defined | H30: B | I30: =$B$5+90 -> 46055 | J30: Member Defined
A31: GATT/CL/GAR/BI-09-C | B31: Read Using Characteristic UUID - Insufficient Authorization | C31: 2019-1 | D31: B | E31: 45873 | F31: Member Defined | H31: B | I31: =$B$5+90 -> 46055 | J31: Member Defined
A32: GATT/CL/GAR/BI-10-C | B32: Read Using Characteristic UUID - Insufficient Authentication | C32: 2019-1 | D32: B | E32: 45873 | F32: Member Defined | H32: B | I32: =$B$5+90 -> 46055 | J32: Member Defined
A33: GATT/CL/GAR/BI-11-C | B33: Read Using Characteristic UUID - Insufficient Encryption Key Size | C33: 2019-1 | D33: B | E33: 45873 | F33: Member Defined | H33: B | I33: =$B$5+90 -> 46055 | J33: Member Defined
A34: GATT/CL/GAR/BI-12-C | B34: Read Long Characteristic Value - Read Not Permitted | D34: B | E34: 45873 | F34: Member Defined | H34: B | I34: =$B$5+90 -> 46055 | J34: Member Defined
A35: GATT/CL/GAR/BI-13-C | B35: Read Long Characteristic Value - Invalid Offset | D35: B | E35: 45873 | F35: Member Defined | H35: B | I35: =$B$5+90 -> 46055 | J35: Member Defined
A36: GATT/CL/GAR/BI-14-C | B36: Read Long Characteristic Value - Invalid Handle | D36: B | E36: 45873 | F36: Member Defined | H36: B | I36: =$B$5+90 -> 46055 | J36: Member Defined
A37: GATT/CL/GAR/BI-15-C | B37: Read Long Characteristic Value - Insufficient Authorization | C37: 2019-1 | D37: B | E37: 45873 | F37: Member Defined | H37: B | I37: =$B$5+90 -> 46055 | J37: Member Defined
A38: GATT/CL/GAR/BI-16-C | B38: Read Long Characteristic Value - Insufficient Authentication | C38: 2019-1 | D38: B | E38: 45873 | F38: Member Defined | H38: B | I38: =$B$5+90 -> 46055 | J38: Member Defined
A39: GATT/CL/GAR/BI-17-C | B39: Read Long Characteristic Value - Insufficient Encryption Key Size | C39: 2019-1 | D39: B | E39: 45873 | F39: Member Defined | H39: B | I39: =$B$5+90 -> 46055 | J39: Member Defined
A40: GATT/CL/GAR/BI-18-C | B40: Read Multiple Characteristic Values - Read Not Permitted | D40: B | E40: 45873 | F40: Member Defined | H40: B | I40: =$B$5+90 -> 46055 | J40: Member Defined
...

Sheet HCI
A1: Test Case Reference List
A2: =Top!B15 & " Conformance" -> Host Controller Interface Conformance | D2: Previous TS | E2: =Top!E15 -> HCI.TS.p37 | H2: TS | I2: =Top!G15 -> HCI.TS.p38 | J2: Available Date | K2: =rel_date -> 45965
A3: =Top!D15 -> Vol 2 Part E, 4.2–6.2 | D3: Previous ICS | E3: =Top!F15 -> HCI.ICS.p32 | H3: ICS | I3: =Top!H15 -> HCI.ICS.p33 | J3: Available Date | K3: =rel_date -> 45965
A4: =Top!A2 -> Release Date | B4: =rel_date -> 45965
D5: Previous ICS | E5: =Top!F16 -> UHCI.ICS.p2 | H5: ICS | I5: =Top!H16 -> UHCI.ICS.p3 | J5: Available Date | K5: =rel_date -> 45965
A6: go to top | D6: Previously published test requirements | H6: Updated requirements through this release
A7: TCID*** | B7: Description | C7: TCRL Package Version Last Updated | D7: TC Category | E7: Active Date | F7: Test System Alternatives | G7: Notes | H7: TC Category | I7: Active Date | J7: Test System Alternatives | K7: Notes
